<sdf version='1.7'>
  <model name='clyde'>
    <link name='base_footprint'>
      <inertial>
        <pose>0.002226 -0.001551 0.027938 0 -0 0</pose>
        <mass>0.207996</mass>
        <inertia>
          <ixx>9.37836e-05</ixx>
          <ixy>-1.59854e-05</ixy>
          <ixz>4.90189e-06</ixz>
          <iyy>0.00020289</iyy>
          <iyz>-9.9545e-07</iyz>
          <izz>0.000278102</izz>
        </inertia>
      </inertial>
      <collision name='base_footprint_fixed_joint_lump__base_link_collision'>
        <pose>0 0 0 0 -0 0</pose>
        <geometry>
          <mesh>
            <scale>0.001 0.001 0.001</scale>
            <uri>file:///workspaces/clyderos2/install/share/clyde_description/src/models/clyde_model/meshes/base_link.stl</uri>
          </mesh>
        </geometry>
        <surface>
          <contact>
            <ode/>
          </contact>
          <friction>
            <ode>
              <mu>0.2</mu>
              <mu2>0.2</mu2>
            </ode>
          </friction>
        </surface>
      </collision>
      <collision name='base_footprint_fixed_joint_lump__front__1_collision_1'>
        <pose>0 0 0 0 -0 0</pose>
        <geometry>
          <mesh>
            <scale>0.001 0.001 0.001</scale>
            <uri>file:///workspaces/clyderos2/install/share/clyde_description/src/models/clyde_model/meshes/front__1.stl</uri>
          </mesh>
        </geometry>
        <surface>
          <contact>
            <ode/>
          </contact>
          <friction>
            <ode>
              <mu>0.2</mu>
              <mu2>0.2</mu2>
            </ode>
          </friction>
        </surface>
      </collision>
      <collision name='base_footprint_fixed_joint_lump__rear__1_collision_2'>
        <pose>0 0 0 0 -0 0</pose>
        <geometry>
          <mesh>
            <scale>0.001 0.001 0.001</scale>
            <uri>file:///workspaces/clyderos2/install/share/clyde_description/src/models/clyde_model/meshes/rear__1.stl</uri>
          </mesh>
        </geometry>
        <surface>
          <contact>
            <ode/>
          </contact>
          <friction>
            <ode>
              <mu>0.2</mu>
              <mu2>0.2</mu2>
            </ode>
          </friction>
        </surface>
      </collision>
      <collision name='base_footprint_fixed_joint_lump__servo_rfs_1_collision_3'>
        <pose>0 0 0 0 -0 0</pose>
        <geometry>
          <mesh>
            <scale>0.001 0.001 0.001</scale>
            <uri>file:///workspaces/clyderos2/install/share/clyde_description/src/models/clyde_model/meshes/servo_rfs_1.stl</uri>
          </mesh>
        </geometry>
        <surface>
          <contact>
            <ode/>
          </contact>
          <friction>
            <ode>
              <mu>0.2</mu>
              <mu2>0.2</mu2>
            </ode>
          </friction>
        </surface>
      </collision>
      <collision name='base_footprint_fixed_joint_lump__servo_lfs_1_collision_4'>
        <pose>0 0 0 0 -0 0</pose>
        <geometry>
          <mesh>
            <scale>0.001 0.001 0.001</scale>
            <uri>file:///workspaces/clyderos2/install/share/clyde_description/src/models/clyde_model/meshes/servo_lfs_1.stl</uri>
          </mesh>
        </geometry>
        <surface>
          <contact>
            <ode/>
          </contact>
          <friction>
            <ode>
              <mu>0.2</mu>
              <mu2>0.2</mu2>
            </ode>
          </friction>
        </surface>
      </collision>
      <collision name='base_footprint_fixed_joint_lump__servo_rrs__1_collision_5'>
        <pose>0 0 0 0 -0 0</pose>
        <geometry>
          <mesh>
            <scale>0.001 0.001 0.001</scale>
            <uri>file:///workspaces/clyderos2/install/share/clyde_description/src/models/clyde_model/meshes/servo_rrs__1.stl</uri>
          </mesh>
        </geometry>
        <surface>
          <contact>
            <ode/>
          </contact>
          <friction>
            <ode>
              <mu>0.2</mu>
              <mu2>0.2</mu2>
            </ode>
          </friction>
        </surface>
      </collision>
      <collision name='base_footprint_fixed_joint_lump__cover_1_collision_6'>
        <pose>0 0 0 0 -0 0</pose>
        <geometry>
          <mesh>
            <scale>0.001 0.001 0.001</scale>
            <uri>file:///workspaces/clyderos2/install/share/clyde_description/src/models/clyde_model/meshes/cover_1.stl</uri>
          </mesh>
        </geometry>
        <surface>
          <contact>
            <ode/>
          </contact>
          <friction>
            <ode>
              <mu>0.2</mu>
              <mu2>0.2</mu2>
            </ode>
          </friction>
        </surface>
      </collision>
      <collision name='base_footprint_fixed_joint_lump__battery_1_collision_7'>
        <pose>0 0 0 0 -0 0</pose>
        <geometry>
          <mesh>
            <scale>0.001 0.001 0.001</scale>
            <uri>file:///workspaces/clyderos2/install/share/clyde_description/src/models/clyde_model/meshes/battery_1.stl</uri>
          </mesh>
        </geometry>
        <surface>
          <contact>
            <ode/>
          </contact>
          <friction>
            <ode>
              <mu>0.2</mu>
              <mu2>0.2</mu2>
            </ode>
          </friction>
        </surface>
      </collision>
      <collision name='base_footprint_fixed_joint_lump__servo_lrs__1_collision_8'>
        <pose>0 0 0 0 -0 0</pose>
        <geometry>
          <mesh>
            <scale>0.001 0.001 0.001</scale>
            <uri>file:///workspaces/clyderos2/install/share/clyde_description/src/models/clyde_model/meshes/servo_lrs__1.stl</uri>
          </mesh>
        </geometry>
        <surface>
          <contact>
            <ode/>
          </contact>
          <friction>
            <ode>
              <mu>0.2</mu>
              <mu2>0.2</mu2>
            </ode>
          </friction>
        </surface>
      </collision>
      <collision name='base_footprint_fixed_joint_lump__c_neck__1_collision_9'>
        <pose>0 0 0 0 -0 0</pose>
        <geometry>
          <mesh>
            <scale>0.001 0.001 0.001</scale>
            <uri>file:///workspaces/clyderos2/install/share/clyde_description/src/models/clyde_model/meshes/c_neck__1.stl</uri>
          </mesh>
        </geometry>
        <surface>
          <contact>
            <ode/>
          </contact>
          <friction>
            <ode>
              <mu>0.2</mu>
              <mu2>0.2</mu2>
            </ode>
          </friction>
        </surface>
      </collision>
      <collision name='base_footprint_fixed_joint_lump__imu_link_collision_10'>
        <pose>0 0 0.03 0 -0 0</pose>
        <geometry>
          <box>
            <size>0.01 0.01 0.01</size>
          </box>
        </geometry>
        <surface>
          <contact>
            <ode/>
          </contact>
          <friction>
            <ode/>
          </friction>
        </surface>
      </collision>
      <visual name='base_footprint_fixed_joint_lump__base_link_visual'>
        <pose>0 0 0 0 -0 0</pose>
        <geometry>
          <mesh>
            <scale>0.001 0.001 0.001</scale>
            <uri>file:///workspaces/clyderos2/install/share/clyde_description/src/models/clyde_model/meshes/base_link.stl</uri>
          </mesh>
        </geometry>
        <material>
          <ambient>255 171 80 1</ambient>
        </material>
      </visual>
      <visual name='base_footprint_fixed_joint_lump__front__1_visual_1'>
        <pose>0 0 0 0 -0 0</pose>
        <geometry>
          <mesh>
            <scale>0.001 0.001 0.001</scale>
            <uri>file:///workspaces/clyderos2/install/share/clyde_description/src/models/clyde_model/meshes/front__1.stl</uri>
          </mesh>
        </geometry>
        <material>
          <ambient>0 167 255 1</ambient>
        </material>
      </visual>
      <visual name='base_footprint_fixed_joint_lump__rear__1_visual_2'>
        <pose>0 0 0 0 -0 0</pose>
        <geometry>
          <mesh>
            <scale>0.001 0.001 0.001</scale>
            <uri>file:///workspaces/clyderos2/install/share/clyde_description/src/models/clyde_model/meshes/rear__1.stl</uri>
          </mesh>
        </geometry>
        <material>
          <ambient>0 167 255 1</ambient>
        </material>
      </visual>
      <visual name='base_footprint_fixed_joint_lump__servo_rfs_1_visual_3'>
        <pose>0 0 0 0 -0 0</pose>
        <geometry>
          <mesh>
            <scale>0.001 0.001 0.001</scale>
            <uri>file:///workspaces/clyderos2/install/share/clyde_description/src/models/clyde_model/meshes/servo_rfs_1.stl</uri>
          </mesh>
        </geometry>
        <material>
          <ambient>39 61 51 1</ambient>
        </material>
      </visual>
      <visual name='base_footprint_fixed_joint_lump__servo_lfs_1_visual_4'>
        <pose>0 0 0 0 -0 0</pose>
        <geometry>
          <mesh>
            <scale>0.001 0.001 0.001</scale>
            <uri>file:///workspaces/clyderos2/install/share/clyde_description/src/models/clyde_model/meshes/servo_lfs_1.stl</uri>
          </mesh>
        </geometry>
        <material>
          <ambient>39 61 51 1</ambient>
        </material>
      </visual>
      <visual name='base_footprint_fixed_joint_lump__servo_rrs__1_visual_5'>
        <pose>0 0 0 0 -0 0</pose>
        <geometry>
          <mesh>
            <scale>0.001 0.001 0.001</scale>
            <uri>file:///workspaces/clyderos2/install/share/clyde_description/src/models/clyde_model/meshes/servo_rrs__1.stl</uri>
          </mesh>
        </geometry>
        <material>
          <ambient>39 61 51 1</ambient>
        </material>
      </visual>
      <visual name='base_footprint_fixed_joint_lump__cover_1_visual_6'>
        <pose>0 0 0 0 -0 0</pose>
        <geometry>
          <mesh>
            <scale>0.001 0.001 0.001</scale>
            <uri>file:///workspaces/clyderos2/install/share/clyde_description/src/models/clyde_model/meshes/cover_1.stl</uri>
          </mesh>
        </geometry>
        <material>
          <ambient>73 73 70 1</ambient>
        </material>
      </visual>
      <visual name='base_footprint_fixed_joint_lump__battery_1_visual_7'>
        <pose>0 0 0 0 -0 0</pose>
        <geometry>
          <mesh>
            <scale>0.001 0.001 0.001</scale>
            <uri>file:///workspaces/clyderos2/install/share/clyde_description/src/models/clyde_model/meshes/battery_1.stl</uri>
          </mesh>
        </geometry>
        <material>
          <ambient>73 73 70 1</ambient>
        </material>
      </visual>
      <visual name='base_footprint_fixed_joint_lump__servo_lrs__1_visual_8'>
        <pose>0 0 0 0 -0 0</pose>
        <geometry>
          <mesh>
            <scale>0.001 0.001 0.001</scale>
            <uri>file:///workspaces/clyderos2/install/share/clyde_description/src/models/clyde_model/meshes/servo_lrs__1.stl</uri>
          </mesh>
        </geometry>
        <material>
          <ambient>39 61 51 1</ambient>
        </material>
      </visual>
      <visual name='base_footprint_fixed_joint_lump__c_neck__1_visual_9'>
        <pose>0 0 0 0 -0 0</pose>
        <geometry>
          <mesh>
            <scale>0.001 0.001 0.001</scale>
            <uri>file:///workspaces/clyderos2/install/share/clyde_description/src/models/clyde_model/meshes/c_neck__1.stl</uri>
          </mesh>
        </geometry>
        <material>
          <ambient>244 229 167 1</ambient>
        </material>
      </visual>
      <visual name='base_footprint_fixed_joint_lump__imu_link_visual_10'>
        <pose>0 0 0.03 0 -0 0</pose>
        <geometry>
          <box>
            <size>0.01 0.01 0.01</size>
          </box>
        </geometry>
      </visual>
      <gravity>1</gravity>
      <self_collide>1</self_collide>
      <sensor name='imu_sensor' type='imu'>
        <plugin name='imu_plugin' filename='libgazebo_ros_imu_sensor.so'>
          <ros>
            <namespace>/clyde</namespace>
            <remapping>~/out:=imu</remapping>
          </ros>
          <initial_orientation_as_reference>0</initial_orientation_as_reference>
        </plugin>
        <always_on>1</always_on>
        <update_rate>100</update_rate>
        <visualize>1</visualize>
        <imu>
          <angular_velocity>
            <x>
              <noise type='gaussian'>
                <mean>0</mean>
                <stddev>0.0002</stddev>
                <bias_mean>7.5e-06</bias_mean>
                <bias_stddev>8e-07</bias_stddev>
              </noise>
            </x>
            <y>
              <noise type='gaussian'>
                <mean>0</mean>
                <stddev>0.0002</stddev>
                <bias_mean>7.5e-06</bias_mean>
                <bias_stddev>8e-07</bias_stddev>
              </noise>
            </y>
            <z>
              <noise type='gaussian'>
                <mean>0</mean>
                <stddev>0.0002</stddev>
                <bias_mean>7.5e-06</bias_mean>
                <bias_stddev>8e-07</bias_stddev>
              </noise>
            </z>
          </angular_velocity>
          <linear_acceleration>
            <x>
              <noise type='gaussian'>
                <mean>0</mean>
                <stddev>0.017</stddev>
                <bias_mean>0.1</bias_mean>
                <bias_stddev>0.001</bias_stddev>
              </noise>
            </x>
            <y>
              <noise type='gaussian'>
                <mean>0</mean>
                <stddev>0.017</stddev>
                <bias_mean>0.1</bias_mean>
                <bias_stddev>0.001</bias_stddev>
              </noise>
            </y>
            <z>
              <noise type='gaussian'>
                <mean>0</mean>
                <stddev>0.017</stddev>
                <bias_mean>0.1</bias_mean>
                <bias_stddev>0.001</bias_stddev>
              </noise>
            </z>
          </linear_acceleration>
        </imu>
        <pose>0 0 0.03 0 -0 0</pose>
      </sensor>
    </link>
    <joint name='shrfs_joint' type='revolute'>
      <pose relative_to='base_footprint'>0.0525 -0.0485 0.022 0 -0 0</pose>
      <parent>base_footprint</parent>
      <child>c_thrf__1</child>
      <axis>
        <xyz>0 1 0</xyz>
        <limit>
          <lower>-1e+16</lower>
          <upper>1e+16</upper>
        </limit>
        <dynamics>
          <spring_reference>0</spring_reference>
          <spring_stiffness>0</spring_stiffness>
        </dynamics>
      </axis>
    </joint>
    <link name='c_thrf__1'>
      <pose relative_to='shrfs_joint'>0 0 0 0 -0 0</pose>
      <inertial>
        <pose>-0.022218 -0.001215 -0.005953 0 -0 0</pose>
        <mass>0.0047131</mass>
        <inertia>
          <ixx>6.06305e-08</ixx>
          <ixy>-1.63518e-08</ixy>
          <ixz>-1.99985e-07</ixz>
          <iyy>7.99936e-07</iyy>
          <iyz>-4.36986e-09</iyz>
          <izz>7.53395e-07</izz>
        </inertia>
      </inertial>
      <collision name='c_thrf__1_collision'>
        <pose>-0.0525 0.0485 -0.022 0 -0 0</pose>
        <geometry>
          <mesh>
            <scale>0.001 0.001 0.001</scale>
            <uri>file:///workspaces/clyderos2/install/share/clyde_description/src/models/clyde_model/meshes/c_thrf__1.stl</uri>
          </mesh>
        </geometry>
        <surface>
          <contact>
            <ode/>
          </contact>
          <friction>
            <ode>
              <mu>0.2</mu>
              <mu2>0.2</mu2>
            </ode>
          </friction>
        </surface>
      </collision>
      <collision name='c_thrf__1_fixed_joint_lump__th_rf_1_collision_1'>
        <pose>-0.0525 0.0485 -0.022 0 -0 0</pose>
        <geometry>
          <mesh>
            <scale>0.001 0.001 0.001</scale>
            <uri>file:///workspaces/clyderos2/install/share/clyde_description/src/models/clyde_model/meshes/th_rf_1.stl</uri>
          </mesh>
        </geometry>
        <surface>
          <contact>
            <ode/>
          </contact>
          <friction>
            <ode>
              <mu>0.2</mu>
              <mu2>0.2</mu2>
            </ode>
          </friction>
        </surface>
      </collision>
      <collision name='c_thrf__1_fixed_joint_lump__tho_rf__1_collision_2'>
        <pose>-0.0525 0.0485 -0.022 0 -0 0</pose>
        <geometry>
          <mesh>
            <scale>0.001 0.001 0.001</scale>
            <uri>file:///workspaces/clyderos2/install/share/clyde_description/src/models/clyde_model/meshes/tho_rf__1.stl</uri>
          </mesh>
        </geometry>
        <surface>
          <contact>
            <ode/>
          </contact>
          <friction>
            <ode>
              <mu>0.2</mu>
              <mu2>0.2</mu2>
            </ode>
          </friction>
        </surface>
      </collision>
      <collision name='c_thrf__1_fixed_joint_lump__c_thorf_1_collision_3'>
        <pose>-0.0525 0.0485 -0.022 0 -0 0</pose>
        <geometry>
          <mesh>
            <scale>0.001 0.001 0.001</scale>
            <uri>file:///workspaces/clyderos2/install/share/clyde_description/src/models/clyde_model/meshes/c_thorf_1.stl</uri>
          </mesh>
        </geometry>
        <surface>
          <contact>
            <ode/>
          </contact>
          <friction>
            <ode>
              <mu>0.2</mu>
              <mu2>0.2</mu2>
            </ode>
          </friction>
        </surface>
      </collision>
      <collision name='c_thrf__1_fixed_joint_lump__tube__1_collision_4'>
        <pose>-0.0525 0.0485 -0.022 0 -0 0</pose>
        <geometry>
          <mesh>
            <scale>0.001 0.001 0.001</scale>
            <uri>file:///workspaces/clyderos2/install/share/clyde_description/src/models/clyde_model/meshes/tube__1.stl</uri>
          </mesh>
        </geometry>
        <surface>
          <contact>
            <ode/>
          </contact>
          <friction>
            <ode>
              <mu>0.2</mu>
              <mu2>0.2</mu2>
            </ode>
          </friction>
        </surface>
      </collision>
      <visual name='c_thrf__1_visual'>
        <pose>-0.0525 0.0485 -0.022 0 -0 0</pose>
        <geometry>
          <mesh>
            <scale>0.001 0.001 0.001</scale>
            <uri>file:///workspaces/clyderos2/install/share/clyde_description/src/models/clyde_model/meshes/c_thrf__1.stl</uri>
          </mesh>
        </geometry>
        <material>
          <ambient>244 229 167 1</ambient>
        </material>
      </visual>
      <visual name='c_thrf__1_fixed_joint_lump__th_rf_1_visual_1'>
        <pose>-0.0525 0.0485 -0.022 0 -0 0</pose>
        <geometry>
          <mesh>
            <scale>0.001 0.001 0.001</scale>
            <uri>file:///workspaces/clyderos2/install/share/clyde_description/src/models/clyde_model/meshes/th_rf_1.stl</uri>
          </mesh>
        </geometry>
        <material>
          <ambient>255 171 80 1</ambient>
        </material>
      </visual>
      <visual name='c_thrf__1_fixed_joint_lump__tho_rf__1_visual_2'>
        <pose>-0.0525 0.0485 -0.022 0 -0 0</pose>
        <geometry>
          <mesh>
            <scale>0.001 0.001 0.001</scale>
            <uri>file:///workspaces/clyderos2/install/share/clyde_description/src/models/clyde_model/meshes/tho_rf__1.stl</uri>
          </mesh>
        </geometry>
        <material>
          <ambient>73 73 70 1</ambient>
        </material>
      </visual>
      <visual name='c_thrf__1_fixed_joint_lump__c_thorf_1_visual_3'>
        <pose>-0.0525 0.0485 -0.022 0 -0 0</pose>
        <geometry>
          <mesh>
            <scale>0.001 0.001 0.001</scale>
            <uri>file:///workspaces/clyderos2/install/share/clyde_description/src/models/clyde_model/meshes/c_thorf_1.stl</uri>
          </mesh>
        </geometry>
        <material>
          <ambient>244 229 167 1</ambient>
        </material>
      </visual>
      <visual name='c_thrf__1_fixed_joint_lump__tube__1_visual_4'>
        <pose>-0.0525 0.0485 -0.022 0 -0 0</pose>
        <geometry>
          <mesh>
            <scale>0.001 0.001 0.001</scale>
            <uri>file:///workspaces/clyderos2/install/share/clyde_description/src/models/clyde_model/meshes/tube__1.stl</uri>
          </mesh>
        </geometry>
        <material>
          <ambient>0 167 255 1</ambient>
        </material>
      </visual>
      <self_collide>1</self_collide>
    </link>
    <joint name='shrft_joint' type='revolute'>
      <pose relative_to='c_thrf__1'>-0.044433 0.00142 -0.011906 0 -0 0</pose>
      <parent>c_thrf__1</parent>
      <child>servos_rf_1</child>
      <axis>
        <xyz>0 1 0</xyz>
        <limit>
          <lower>-1e+16</lower>
          <upper>1e+16</upper>
        </limit>
        <dynamics>
          <spring_reference>0</spring_reference>
          <spring_stiffness>0</spring_stiffness>
        </dynamics>
      </axis>
    </joint>
    <link name='servos_rf_1'>
      <pose relative_to='shrft_joint'>0 0 0 0 -0 0</pose>
      <inertial>
        <pose>0.007653 0.012412 -0.000544 0 -0 0</pose>
        <mass>0.0185326</mass>
        <inertia>
          <ixx>1.00116e-06</ixx>
          <ixy>-2.08202e-08</ixy>
          <ixz>1.04994e-08</ixz>
          <iyy>2.47087e-06</iyy>
          <iyz>4.64478e-10</iyz>
          <izz>2.47155e-06</izz>
        </inertia>
      </inertial>
      <collision name='servos_rf_1_collision'>
        <pose>-0.008067 0.04708 -0.010094 0 -0 0</pose>
        <geometry>
          <mesh>
            <scale>0.001 0.001 0.001</scale>
            <uri>file:///workspaces/clyderos2/install/share/clyde_description/src/models/clyde_model/meshes/servos_rf_1.stl</uri>
          </mesh>
        </geometry>
        <surface>
          <contact>
            <ode/>
          </contact>
          <friction>
            <ode>
              <mu>0.2</mu>
              <mu2>0.2</mu2>
            </ode>
          </friction>
        </surface>
      </collision>
      <collision name='servos_rf_1_fixed_joint_lump__shank_rf_1_collision_1'>
        <pose>-0.008067 0.04708 -0.010094 0 -0 0</pose>
        <geometry>
          <mesh>
            <scale>0.001 0.001 0.001</scale>
            <uri>file:///workspaces/clyderos2/install/share/clyde_description/src/models/clyde_model/meshes/shank_rf_1.stl</uri>
          </mesh>
        </geometry>
        <surface>
          <contact>
            <ode/>
          </contact>
          <friction>
            <ode>
              <mu>0.2</mu>
              <mu2>0.2</mu2>
            </ode>
          </friction>
        </surface>
      </collision>
      <visual name='servos_rf_1_visual'>
        <pose>-0.008067 0.04708 -0.010094 0 -0 0</pose>
        <geometry>
          <mesh>
            <scale>0.001 0.001 0.001</scale>
            <uri>file:///workspaces/clyderos2/install/share/clyde_description/src/models/clyde_model/meshes/servos_rf_1.stl</uri>
          </mesh>
        </geometry>
        <material>
          <ambient>39 61 51 1</ambient>
        </material>
      </visual>
      <visual name='servos_rf_1_fixed_joint_lump__shank_rf_1_visual_1'>
        <pose>-0.008067 0.04708 -0.010094 0 -0 0</pose>
        <geometry>
          <mesh>
            <scale>0.001 0.001 0.001</scale>
            <uri>file:///workspaces/clyderos2/install/share/clyde_description/src/models/clyde_model/meshes/shank_rf_1.stl</uri>
          </mesh>
        </geometry>
        <material>
          <ambient>73 73 70 1</ambient>
        </material>
      </visual>
      <self_collide>1</self_collide>
    </link>
    <joint name='shlfs_joint' type='revolute'>
      <pose relative_to='base_footprint'>0.0525 0.0485 0.022 0 -0 0</pose>
      <parent>base_footprint</parent>
      <child>c_thlf_1</child>
      <axis>
        <xyz>0 1 0</xyz>
        <limit>
          <lower>-1e+16</lower>
          <upper>1e+16</upper>
        </limit>
        <dynamics>
          <spring_reference>0</spring_reference>
          <spring_stiffness>0</spring_stiffness>
        </dynamics>
      </axis>
    </joint>
    <link name='c_thlf_1'>
      <pose relative_to='shlfs_joint'>0 0 0 0 -0 0</pose>
      <inertial>
        <pose>-0.022218 0.001215 -0.005953 0 -0 0</pose>
        <mass>0.00471308</mass>
        <inertia>
          <ixx>6.06299e-08</ixx>
          <ixy>1.63516e-08</ixy>
          <ixz>-1.99983e-07</ixz>
          <iyy>7.99931e-07</iyy>
          <iyz>4.36994e-09</iyz>
          <izz>7.5339e-07</izz>
        </inertia>
      </inertial>
      <collision name='c_thlf_1_collision'>
        <pose>-0.0525 -0.0485 -0.022 0 -0 0</pose>
        <geometry>
          <mesh>
            <scale>0.001 0.001 0.001</scale>
            <uri>file:///workspaces/clyderos2/install/share/clyde_description/src/models/clyde_model/meshes/c_thlf_1.stl</uri>
          </mesh>
        </geometry>
        <surface>
          <contact>
            <ode/>
          </contact>
          <friction>
            <ode>
              <mu>0.2</mu>
              <mu2>0.2</mu2>
            </ode>
          </friction>
        </surface>
      </collision>
      <collision name='c_thlf_1_fixed_joint_lump__th_lf_1_collision_1'>
        <pose>-0.0525 -0.0485 -0.022 0 -0 0</pose>
        <geometry>
          <mesh>
            <scale>0.001 0.001 0.001</scale>
            <uri>file:///workspaces/clyderos2/install/share/clyde_description/src/models/clyde_model/meshes/th_lf_1.stl</uri>
          </mesh>
        </geometry>
        <surface>
          <contact>
            <ode/>
          </contact>
          <friction>
            <ode>
              <mu>0.2</mu>
              <mu2>0.2</mu2>
            </ode>
          </friction>
        </surface>
      </collision>
      <collision name='c_thlf_1_fixed_joint_lump__tho_lf_1_collision_2'>
        <pose>-0.0525 -0.0485 -0.022 0 -0 0</pose>
        <geometry>
          <mesh>
            <scale>0.001 0.001 0.001</scale>
            <uri>file:///workspaces/clyderos2/install/share/clyde_description/src/models/clyde_model/meshes/tho_lf_1.stl</uri>
          </mesh>
        </geometry>
        <surface>
          <contact>
            <ode/>
          </contact>
          <friction>
            <ode>
              <mu>0.2</mu>
              <mu2>0.2</mu2>
            </ode>
          </friction>
        </surface>
      </collision>
      <collision name='c_thlf_1_fixed_joint_lump__c_tholf_1_collision_3'>
        <pose>-0.0525 -0.0485 -0.022 0 -0 0</pose>
        <geometry>
          <mesh>
            <scale>0.001 0.001 0.001</scale>
            <uri>file:///workspaces/clyderos2/install/share/clyde_description/src/models/clyde_model/meshes/c_tholf_1.stl</uri>
          </mesh>
        </geometry>
        <surface>
          <contact>
            <ode/>
          </contact>
          <friction>
            <ode>
              <mu>0.2</mu>
              <mu2>0.2</mu2>
            </ode>
          </friction>
        </surface>
      </collision>
      <collision name='c_thlf_1_fixed_joint_lump__tube_lf_1_collision_4'>
        <pose>-0.0525 -0.0485 -0.022 0 -0 0</pose>
        <geometry>
          <mesh>
            <scale>0.001 0.001 0.001</scale>
            <uri>file:///workspaces/clyderos2/install/share/clyde_description/src/models/clyde_model/meshes/tube_lf_1.stl</uri>
          </mesh>
        </geometry>
        <surface>
          <contact>
            <ode/>
          </contact>
          <friction>
            <ode>
              <mu>0.2</mu>
              <mu2>0.2</mu2>
            </ode>
          </friction>
        </surface>
      </collision>
      <visual name='c_thlf_1_visual'>
        <pose>-0.0525 -0.0485 -0.022 0 -0 0</pose>
        <geometry>
          <mesh>
            <scale>0.001 0.001 0.001</scale>
            <uri>file:///workspaces/clyderos2/install/share/clyde_description/src/models/clyde_model/meshes/c_thlf_1.stl</uri>
          </mesh>
        </geometry>
        <material>
          <ambient>244 229 167 1</ambient>
        </material>
      </visual>
      <visual name='c_thlf_1_fixed_joint_lump__th_lf_1_visual_1'>
        <pose>-0.0525 -0.0485 -0.022 0 -0 0</pose>
        <geometry>
          <mesh>
            <scale>0.001 0.001 0.001</scale>
            <uri>file:///workspaces/clyderos2/install/share/clyde_description/src/models/clyde_model/meshes/th_lf_1.stl</uri>
          </mesh>
        </geometry>
        <material>
          <ambient>255 171 80 1</ambient>
        </material>
      </visual>
      <visual name='c_thlf_1_fixed_joint_lump__tho_lf_1_visual_2'>
        <pose>-0.0525 -0.0485 -0.022 0 -0 0</pose>
        <geometry>
          <mesh>
            <scale>0.001 0.001 0.001</scale>
            <uri>file:///workspaces/clyderos2/install/share/clyde_description/src/models/clyde_model/meshes/tho_lf_1.stl</uri>
          </mesh>
        </geometry>
        <material>
          <ambient>73 73 70 1</ambient>
        </material>
      </visual>
      <visual name='c_thlf_1_fixed_joint_lump__c_tholf_1_visual_3'>
        <pose>-0.0525 -0.0485 -0.022 0 -0 0</pose>
        <geometry>
          <mesh>
            <scale>0.001 0.001 0.001</scale>
            <uri>file:///workspaces/clyderos2/install/share/clyde_description/src/models/clyde_model/meshes/c_tholf_1.stl</uri>
          </mesh>
        </geometry>
        <material>
          <ambient>244 229 167 1</ambient>
        </material>
      </visual>
      <visual name='c_thlf_1_fixed_joint_lump__tube_lf_1_visual_4'>
        <pose>-0.0525 -0.0485 -0.022 0 -0 0</pose>
        <geometry>
          <mesh>
            <scale>0.001 0.001 0.001</scale>
            <uri>file:///workspaces/clyderos2/install/share/clyde_description/src/models/clyde_model/meshes/tube_lf_1.stl</uri>
          </mesh>
        </geometry>
        <material>
          <ambient>0 167 255 1</ambient>
        </material>
      </visual>
      <self_collide>1</self_collide>
    </link>
    <joint name='shlft_joint' type='revolute'>
      <pose relative_to='c_thlf_1'>-0.044433 -0.00142 -0.011906 0 -0 0</pose>
      <parent>c_thlf_1</parent>
      <child>servos_lf_1</child>
      <axis>
        <xyz>0 1 0</xyz>
        <limit>
          <lower>-1e+16</lower>
          <upper>1e+16</upper>
        </limit>
        <dynamics>
          <spring_reference>0</spring_reference>
          <spring_stiffness>0</spring_stiffness>
        </dynamics>
      </axis>
    </joint>
    <link name='servos_lf_1'>
      <pose relative_to='shlft_joint'>0 0 0 0 -0 0</pose>
      <inertial>
        <pose>0.007653 -0.012412 -0.000544 0 -0 0</pose>
        <mass>0.0185326</mass>
        <inertia>
          <ixx>1.00116e-06</ixx>
          <ixy>2.08202e-08</ixy>
          <ixz>1.04995e-08</ixz>
          <iyy>2.47087e-06</iyy>
          <iyz>-4.64481e-10</iyz>
          <izz>2.47156e-06</izz>
        </inertia>
      </inertial>
      <collision name='servos_lf_1_collision'>
        <pose>-0.008067 -0.04708 -0.010094 0 -0 0</pose>
        <geometry>
          <mesh>
            <scale>0.001 0.001 0.001</scale>
            <uri>file:///workspaces/clyderos2/install/share/clyde_description/src/models/clyde_model/meshes/servos_lf_1.stl</uri>
          </mesh>
        </geometry>
        <surface>
          <contact>
            <ode/>
          </contact>
          <friction>
            <ode>
              <mu>0.2</mu>
              <mu2>0.2</mu2>
            </ode>
          </friction>
        </surface>
      </collision>
      <collision name='servos_lf_1_fixed_joint_lump__shank_lf_1_collision_1'>
        <pose>-0.008067 -0.04708 -0.010094 0 -0 0</pose>
        <geometry>
          <mesh>
            <scale>0.001 0.001 0.001</scale>
            <uri>file:///workspaces/clyderos2/install/share/clyde_description/src/models/clyde_model/meshes/shank_lf_1.stl</uri>
          </mesh>
        </geometry>
        <surface>
          <contact>
            <ode/>
          </contact>
          <friction>
            <ode>
              <mu>0.2</mu>
              <mu2>0.2</mu2>
            </ode>
          </friction>
        </surface>
      </collision>
      <visual name='servos_lf_1_visual'>
        <pose>-0.008067 -0.04708 -0.010094 0 -0 0</pose>
        <geometry>
          <mesh>
            <scale>0.001 0.001 0.001</scale>
            <uri>file:///workspaces/clyderos2/install/share/clyde_description/src/models/clyde_model/meshes/servos_lf_1.stl</uri>
          </mesh>
        </geometry>
        <material>
          <ambient>39 61 51 1</ambient>
        </material>
      </visual>
      <visual name='servos_lf_1_fixed_joint_lump__shank_lf_1_visual_1'>
        <pose>-0.008067 -0.04708 -0.010094 0 -0 0</pose>
        <geometry>
          <mesh>
            <scale>0.001 0.001 0.001</scale>
            <uri>file:///workspaces/clyderos2/install/share/clyde_description/src/models/clyde_model/meshes/shank_lf_1.stl</uri>
          </mesh>
        </geometry>
        <material>
          <ambient>73 73 70 1</ambient>
        </material>
      </visual>
      <self_collide>1</self_collide>
    </link>
    <joint name='shrrs_joint' type='revolute'>
      <pose relative_to='base_footprint'>-0.0525 -0.0485 0.022 0 -0 0</pose>
      <parent>base_footprint</parent>
      <child>c_thrr_1</child>
      <axis>
        <xyz>0 -1 0</xyz>
        <limit>
          <lower>-1e+16</lower>
          <upper>1e+16</upper>
        </limit>
        <dynamics>
          <spring_reference>0</spring_reference>
          <spring_stiffness>0</spring_stiffness>
        </dynamics>
      </axis>
    </joint>
    <link name='c_thrr_1'>
      <pose relative_to='shrrs_joint'>0 0 0 0 -0 0</pose>
      <inertial>
        <pose>-0.022226 -0.001215 -0.005953 0 -0 0</pose>
        <mass>0.0047131</mass>
        <inertia>
          <ixx>6.06307e-08</ixx>
          <ixy>-1.63522e-08</ixy>
          <ixz>-1.99985e-07</ixz>
          <iyy>7.9994e-07</iyy>
          <iyz>-4.36991e-09</iyz>
          <izz>7.53399e-07</izz>
        </inertia>
      </inertial>
      <collision name='c_thrr_1_collision'>
        <pose>0.0525 0.0485 -0.022 0 -0 0</pose>
        <geometry>
          <mesh>
            <scale>0.001 0.001 0.001</scale>
            <uri>file:///workspaces/clyderos2/install/share/clyde_description/src/models/clyde_model/meshes/c_thrr_1.stl</uri>
          </mesh>
        </geometry>
        <surface>
          <contact>
            <ode/>
          </contact>
          <friction>
            <ode>
              <mu>0.2</mu>
              <mu2>0.2</mu2>
            </ode>
          </friction>
        </surface>
      </collision>
      <collision name='c_thrr_1_fixed_joint_lump__th_rr_1_collision_1'>
        <pose>0.0525 0.0485 -0.022 0 -0 0</pose>
        <geometry>
          <mesh>
            <scale>0.001 0.001 0.001</scale>
            <uri>file:///workspaces/clyderos2/install/share/clyde_description/src/models/clyde_model/meshes/th_rr_1.stl</uri>
          </mesh>
        </geometry>
        <surface>
          <contact>
            <ode/>
          </contact>
          <friction>
            <ode>
              <mu>0.2</mu>
              <mu2>0.2</mu2>
            </ode>
          </friction>
        </surface>
      </collision>
      <collision name='c_thrr_1_fixed_joint_lump__tho_rr_1_collision_2'>
        <pose>0.0525 0.0485 -0.022 0 -0 0</pose>
        <geometry>
          <mesh>
            <scale>0.001 0.001 0.001</scale>
            <uri>file:///workspaces/clyderos2/install/share/clyde_description/src/models/clyde_model/meshes/tho_rr_1.stl</uri>
          </mesh>
        </geometry>
        <surface>
          <contact>
            <ode/>
          </contact>
          <friction>
            <ode>
              <mu>0.2</mu>
              <mu2>0.2</mu2>
            </ode>
          </friction>
        </surface>
      </collision>
      <collision name='c_thrr_1_fixed_joint_lump__c_thorr_1_collision_3'>
        <pose>0.0525 0.0485 -0.022 0 -0 0</pose>
        <geometry>
          <mesh>
            <scale>0.001 0.001 0.001</scale>
            <uri>file:///workspaces/clyderos2/install/share/clyde_description/src/models/clyde_model/meshes/c_thorr_1.stl</uri>
          </mesh>
        </geometry>
        <surface>
          <contact>
            <ode/>
          </contact>
          <friction>
            <ode>
              <mu>0.2</mu>
              <mu2>0.2</mu2>
            </ode>
          </friction>
        </surface>
      </collision>
      <collision name='c_thrr_1_fixed_joint_lump__tube_rr_1_collision_4'>
        <pose>0.0525 0.0485 -0.022 0 -0 0</pose>
        <geometry>
          <mesh>
            <scale>0.001 0.001 0.001</scale>
            <uri>file:///workspaces/clyderos2/install/share/clyde_description/src/models/clyde_model/meshes/tube_rr_1.stl</uri>
          </mesh>
        </geometry>
        <surface>
          <contact>
            <ode/>
          </contact>
          <friction>
            <ode>
              <mu>0.2</mu>
              <mu2>0.2</mu2>
            </ode>
          </friction>
        </surface>
      </collision>
      <visual name='c_thrr_1_visual'>
        <pose>0.0525 0.0485 -0.022 0 -0 0</pose>
        <geometry>
          <mesh>
            <scale>0.001 0.001 0.001</scale>
            <uri>file:///workspaces/clyderos2/install/share/clyde_description/src/models/clyde_model/meshes/c_thrr_1.stl</uri>
          </mesh>
        </geometry>
        <material>
          <ambient>244 229 167 1</ambient>
        </material>
      </visual>
      <visual name='c_thrr_1_fixed_joint_lump__th_rr_1_visual_1'>
        <pose>0.0525 0.0485 -0.022 0 -0 0</pose>
        <geometry>
          <mesh>
            <scale>0.001 0.001 0.001</scale>
            <uri>file:///workspaces/clyderos2/install/share/clyde_description/src/models/clyde_model/meshes/th_rr_1.stl</uri>
          </mesh>
        </geometry>
        <material>
          <ambient>255 171 80 1</ambient>
        </material>
      </visual>
      <visual name='c_thrr_1_fixed_joint_lump__tho_rr_1_visual_2'>
        <pose>0.0525 0.0485 -0.022 0 -0 0</pose>
        <geometry>
          <mesh>
            <scale>0.001 0.001 0.001</scale>
            <uri>file:///workspaces/clyderos2/install/share/clyde_description/src/models/clyde_model/meshes/tho_rr_1.stl</uri>
          </mesh>
        </geometry>
        <material>
          <ambient>73 73 70 1</ambient>
        </material>
      </visual>
      <visual name='c_thrr_1_fixed_joint_lump__c_thorr_1_visual_3'>
        <pose>0.0525 0.0485 -0.022 0 -0 0</pose>
        <geometry>
          <mesh>
            <scale>0.001 0.001 0.001</scale>
            <uri>file:///workspaces/clyderos2/install/share/clyde_description/src/models/clyde_model/meshes/c_thorr_1.stl</uri>
          </mesh>
        </geometry>
        <material>
          <ambient>244 229 167 1</ambient>
        </material>
      </visual>
      <visual name='c_thrr_1_fixed_joint_lump__tube_rr_1_visual_4'>
        <pose>0.0525 0.0485 -0.022 0 -0 0</pose>
        <geometry>
          <mesh>
            <scale>0.001 0.001 0.001</scale>
            <uri>file:///workspaces/clyderos2/install/share/clyde_description/src/models/clyde_model/meshes/tube_rr_1.stl</uri>
          </mesh>
        </geometry>
        <material>
          <ambient>0 167 255 1</ambient>
        </material>
      </visual>
      <self_collide>1</self_collide>
    </link>
    <joint name='shrrt_joint' type='revolute'>
      <pose relative_to='c_thrr_1'>-0.044433 0.00142 -0.011906 0 -0 0</pose>
      <parent>c_thrr_1</parent>
      <child>servos_rr_1</child>
      <axis>
        <xyz>0 1 0</xyz>
        <limit>
          <lower>-1e+16</lower>
          <upper>1e+16</upper>
        </limit>
        <dynamics>
          <spring_reference>0</spring_reference>
          <spring_stiffness>0</spring_stiffness>
        </dynamics>
      </axis>
    </joint>
    <link name='servos_rr_1'>
      <pose relative_to='shrrt_joint'>0 0 0 0 -0 0</pose>
      <inertial>
        <pose>0.007653 0.012412 -0.000544 0 -0 0</pose>
        <mass>0.0185326</mass>
        <inertia>
          <ixx>1.00116e-06</ixx>
          <ixy>-2.08189e-08</ixy>
          <ixz>1.04987e-08</ixz>
          <iyy>2.47081e-06</iyy>
          <iyz>4.64478e-10</iyz>
          <izz>2.4715e-06</izz>
        </inertia>
      </inertial>
      <collision name='servos_rr_1_collision'>
        <pose>0.096933 0.04708 -0.010094 0 -0 0</pose>
        <geometry>
          <mesh>
            <scale>0.001 0.001 0.001</scale>
            <uri>file:///workspaces/clyderos2/install/share/clyde_description/src/models/clyde_model/meshes/servos_rr_1.stl</uri>
          </mesh>
        </geometry>
        <surface>
          <contact>
            <ode/>
          </contact>
          <friction>
            <ode>
              <mu>0.2</mu>
              <mu2>0.2</mu2>
            </ode>
          </friction>
        </surface>
      </collision>
      <collision name='servos_rr_1_fixed_joint_lump__shank_rr_1_collision_1'>
        <pose>0.096933 0.04708 -0.010094 0 -0 0</pose>
        <geometry>
          <mesh>
            <scale>0.001 0.001 0.001</scale>
            <uri>file:///workspaces/clyderos2/install/share/clyde_description/src/models/clyde_model/meshes/shank_rr_1.stl</uri>
          </mesh>
        </geometry>
        <surface>
          <contact>
            <ode/>
          </contact>
          <friction>
            <ode>
              <mu>0.2</mu>
              <mu2>0.2</mu2>
            </ode>
          </friction>
        </surface>
      </collision>
      <visual name='servos_rr_1_visual'>
        <pose>0.096933 0.04708 -0.010094 0 -0 0</pose>
        <geometry>
          <mesh>
            <scale>0.001 0.001 0.001</scale>
            <uri>file:///workspaces/clyderos2/install/share/clyde_description/src/models/clyde_model/meshes/servos_rr_1.stl</uri>
          </mesh>
        </geometry>
        <material>
          <ambient>39 61 51 1</ambient>
        </material>
      </visual>
      <visual name='servos_rr_1_fixed_joint_lump__shank_rr_1_visual_1'>
        <pose>0.096933 0.04708 -0.010094 0 -0 0</pose>
        <geometry>
          <mesh>
            <scale>0.001 0.001 0.001</scale>
            <uri>file:///workspaces/clyderos2/install/share/clyde_description/src/models/clyde_model/meshes/shank_rr_1.stl</uri>
          </mesh>
        </geometry>
        <material>
          <ambient>73 73 70 1</ambient>
        </material>
      </visual>
      <self_collide>1</self_collide>
    </link>
    <joint name='shlrs_joint' type='revolute'>
      <pose relative_to='base_footprint'>-0.0525 0.0485 0.022 0 -0 0</pose>
      <parent>base_footprint</parent>
      <child>c_thlr_1</child>
      <axis>
        <xyz>0 -1 0</xyz>
        <limit>
          <lower>-1e+16</lower>
          <upper>1e+16</upper>
        </limit>
        <dynamics>
          <spring_reference>0</spring_reference>
          <spring_stiffness>0</spring_stiffness>
        </dynamics>
      </axis>
    </joint>
    <link name='c_thlr_1'>
      <pose relative_to='shlrs_joint'>0 0 0 0 -0 0</pose>
      <inertial>
        <pose>-0.022226 0.001215 -0.005953 0 -0 0</pose>
        <mass>0.00471308</mass>
        <inertia>
          <ixx>6.06299e-08</ixx>
          <ixy>1.6352e-08</ixy>
          <ixz>-1.99984e-07</ixz>
          <iyy>7.99935e-07</iyy>
          <iyz>4.36999e-09</iyz>
          <izz>7.53394e-07</izz>
        </inertia>
      </inertial>
      <collision name='c_thlr_1_collision'>
        <pose>0.0525 -0.0485 -0.022 0 -0 0</pose>
        <geometry>
          <mesh>
            <scale>0.001 0.001 0.001</scale>
            <uri>file:///workspaces/clyderos2/install/share/clyde_description/src/models/clyde_model/meshes/c_thlr_1.stl</uri>
          </mesh>
        </geometry>
        <surface>
          <contact>
            <ode/>
          </contact>
          <friction>
            <ode>
              <mu>0.2</mu>
              <mu2>0.2</mu2>
            </ode>
          </friction>
        </surface>
      </collision>
      <collision name='c_thlr_1_fixed_joint_lump__th_lr__1_collision_1'>
        <pose>0.0525 -0.0485 -0.022 0 -0 0</pose>
        <geometry>
          <mesh>
            <scale>0.001 0.001 0.001</scale>
            <uri>file:///workspaces/clyderos2/install/share/clyde_description/src/models/clyde_model/meshes/th_lr__1.stl</uri>
          </mesh>
        </geometry>
        <surface>
          <contact>
            <ode/>
          </contact>
          <friction>
            <ode>
              <mu>0.2</mu>
              <mu2>0.2</mu2>
            </ode>
          </friction>
        </surface>
      </collision>
      <collision name='c_thlr_1_fixed_joint_lump__tho_lr_1_collision_2'>
        <pose>0.0525 -0.0485 -0.022 0 -0 0</pose>
        <geometry>
          <mesh>
            <scale>0.001 0.001 0.001</scale>
            <uri>file:///workspaces/clyderos2/install/share/clyde_description/src/models/clyde_model/meshes/tho_lr_1.stl</uri>
          </mesh>
        </geometry>
        <surface>
          <contact>
            <ode/>
          </contact>
          <friction>
            <ode>
              <mu>0.2</mu>
              <mu2>0.2</mu2>
            </ode>
          </friction>
        </surface>
      </collision>
      <collision name='c_thlr_1_fixed_joint_lump__c_tholr__1_collision_3'>
        <pose>0.0525 -0.0485 -0.022 0 -0 0</pose>
        <geometry>
          <mesh>
            <scale>0.001 0.001 0.001</scale>
            <uri>file:///workspaces/clyderos2/install/share/clyde_description/src/models/clyde_model/meshes/c_tholr__1.stl</uri>
          </mesh>
        </geometry>
        <surface>
          <contact>
            <ode/>
          </contact>
          <friction>
            <ode>
              <mu>0.2</mu>
              <mu2>0.2</mu2>
            </ode>
          </friction>
        </surface>
      </collision>
      <collision name='c_thlr_1_fixed_joint_lump__tube_lr_1_collision_4'>
        <pose>0.0525 -0.0485 -0.022 0 -0 0</pose>
        <geometry>
          <mesh>
            <scale>0.001 0.001 0.001</scale>
            <uri>file:///workspaces/clyderos2/install/share/clyde_description/src/models/clyde_model/meshes/tube_lr_1.stl</uri>
          </mesh>
        </geometry>
        <surface>
          <contact>
            <ode/>
          </contact>
          <friction>
            <ode>
              <mu>0.2</mu>
              <mu2>0.2</mu2>
            </ode>
          </friction>
        </surface>
      </collision>
      <visual name='c_thlr_1_visual'>
        <pose>0.0525 -0.0485 -0.022 0 -0 0</pose>
        <geometry>
          <mesh>
            <scale>0.001 0.001 0.001</scale>
            <uri>file:///workspaces/clyderos2/install/share/clyde_description/src/models/clyde_model/meshes/c_thlr_1.stl</uri>
          </mesh>
        </geometry>
        <material>
          <ambient>244 229 167 1</ambient>
        </material>
      </visual>
      <visual name='c_thlr_1_fixed_joint_lump__th_lr__1_visual_1'>
        <pose>0.0525 -0.0485 -0.022 0 -0 0</pose>
        <geometry>
          <mesh>
            <scale>0.001 0.001 0.001</scale>
            <uri>file:///workspaces/clyderos2/install/share/clyde_description/src/models/clyde_model/meshes/th_lr__1.stl</uri>
          </mesh>
        </geometry>
        <material>
          <ambient>255 171 80 1</ambient>
        </material>
      </visual>
      <visual name='c_thlr_1_fixed_joint_lump__tho_lr_1_visual_2'>
        <pose>0.0525 -0.0485 -0.022 0 -0 0</pose>
        <geometry>
          <mesh>
            <scale>0.001 0.001 0.001</scale>
            <uri>file:///workspaces/clyderos2/install/share/clyde_description/src/models/clyde_model/meshes/tho_lr_1.stl</uri>
          </mesh>
        </geometry>
        <material>
          <ambient>73 73 70 1</ambient>
        </material>
      </visual>
      <visual name='c_thlr_1_fixed_joint_lump__c_tholr__1_visual_3'>
        <pose>0.0525 -0.0485 -0.022 0 -0 0</pose>
        <geometry>
          <mesh>
            <scale>0.001 0.001 0.001</scale>
            <uri>file:///workspaces/clyderos2/install/share/clyde_description/src/models/clyde_model/meshes/c_tholr__1.stl</uri>
          </mesh>
        </geometry>
        <material>
          <ambient>244 229 167 1</ambient>
        </material>
      </visual>
      <visual name='c_thlr_1_fixed_joint_lump__tube_lr_1_visual_4'>
        <pose>0.0525 -0.0485 -0.022 0 -0 0</pose>
        <geometry>
          <mesh>
            <scale>0.001 0.001 0.001</scale>
            <uri>file:///workspaces/clyderos2/install/share/clyde_description/src/models/clyde_model/meshes/tube_lr_1.stl</uri>
          </mesh>
        </geometry>
        <material>
          <ambient>0 167 255 1</ambient>
        </material>
      </visual>
      <self_collide>1</self_collide>
    </link>
    <joint name='shlrt_joint' type='revolute'>
      <pose relative_to='c_thlr_1'>-0.044433 -0.001418 -0.011906 0 -0 0</pose>
      <parent>c_thlr_1</parent>
      <child>servos_lr_1</child>
      <axis>
        <xyz>0 1 0</xyz>
        <limit>
          <lower>-1e+16</lower>
          <upper>1e+16</upper>
        </limit>
        <dynamics>
          <spring_reference>0</spring_reference>
          <spring_stiffness>0</spring_stiffness>
        </dynamics>
      </axis>
    </joint>
    <link name='servos_lr_1'>
      <pose relative_to='shlrt_joint'>0 0 0 0 -0 0</pose>
      <inertial>
        <pose>0.007653 -0.012414 -0.000544 0 -0 0</pose>
        <mass>0.0185326</mass>
        <inertia>
          <ixx>1.00116e-06</ixx>
          <ixy>2.08189e-08</ixy>
          <ixz>1.04988e-08</ixz>
          <iyy>2.47081e-06</iyy>
          <iyz>-4.64481e-10</iyz>
          <izz>2.4715e-06</izz>
        </inertia>
      </inertial>
      <collision name='servos_lr_1_collision'>
        <pose>0.096933 -0.047082 -0.010094 0 -0 0</pose>
        <geometry>
          <mesh>
            <scale>0.001 0.001 0.001</scale>
            <uri>file:///workspaces/clyderos2/install/share/clyde_description/src/models/clyde_model/meshes/servos_lr_1.stl</uri>
          </mesh>
        </geometry>
        <surface>
          <contact>
            <ode/>
          </contact>
          <friction>
            <ode>
              <mu>0.2</mu>
              <mu2>0.2</mu2>
            </ode>
          </friction>
        </surface>
      </collision>
      <collision name='servos_lr_1_fixed_joint_lump__shank_lr_1_collision_1'>
        <pose>0.096933 -0.047082 -0.010094 0 -0 0</pose>
        <geometry>
          <mesh>
            <scale>0.001 0.001 0.001</scale>
            <uri>file:///workspaces/clyderos2/install/share/clyde_description/src/models/clyde_model/meshes/shank_lr_1.stl</uri>
          </mesh>
        </geometry>
        <surface>
          <contact>
            <ode/>
          </contact>
          <friction>
            <ode>
              <mu>0.2</mu>
              <mu2>0.2</mu2>
            </ode>
          </friction>
        </surface>
      </collision>
      <visual name='servos_lr_1_visual'>
        <pose>0.096933 -0.047082 -0.010094 0 -0 0</pose>
        <geometry>
          <mesh>
            <scale>0.001 0.001 0.001</scale>
            <uri>file:///workspaces/clyderos2/install/share/clyde_description/src/models/clyde_model/meshes/servos_lr_1.stl</uri>
          </mesh>
        </geometry>
        <material>
          <ambient>39 61 51 1</ambient>
        </material>
      </visual>
      <visual name='servos_lr_1_fixed_joint_lump__shank_lr_1_visual_1'>
        <pose>0.096933 -0.047082 -0.010094 0 -0 0</pose>
        <geometry>
          <mesh>
            <scale>0.001 0.001 0.001</scale>
            <uri>file:///workspaces/clyderos2/install/share/clyde_description/src/models/clyde_model/meshes/shank_lr_1.stl</uri>
          </mesh>
        </geometry>
        <material>
          <ambient>73 73 70 1</ambient>
        </material>
      </visual>
      <self_collide>1</self_collide>
    </link>
    <joint name='neck_joint' type='revolute'>
      <pose relative_to='base_footprint'>0.047554 0 0.035941 0.328142 -0.100934 0.592231</pose>
      <parent>base_footprint</parent>
      <child>servo_neck__1</child>
      <axis>
        <xyz>-0.5 0 -0.866025</xyz>
        <limit>
          <lower>-1e+16</lower>
          <upper>1e+16</upper>
        </limit>
        <dynamics>
          <spring_reference>0</spring_reference>
          <spring_stiffness>0</spring_stiffness>
        </dynamics>
      </axis>
    </joint>
    <link name='servo_neck__1'>
      <pose relative_to='neck_joint'>0 0 0 0 -0 0</pose>
      <inertial>
        <pose>0.01396 -0.004473 0.013388 0 -0 0</pose>
        <mass>0.0248334</mass>
        <inertia>
          <ixx>5.68714e-06</ixx>
          <ixy>1.61178e-07</ixy>
          <ixz>-1.23976e-06</ixz>
          <iyy>6.59631e-06</iyy>
          <iyz>2.03647e-07</iyz>
          <izz>4.97167e-06</izz>
        </inertia>
      </inertial>
      <collision name='servo_neck__1_collision'>
        <pose>-0.047554 0 -0.035941 0 -0 0</pose>
        <geometry>
          <mesh>
            <scale>0.001 0.001 0.001</scale>
            <uri>file:///workspaces/clyderos2/install/share/clyde_description/src/models/clyde_model/meshes/servo_neck__1.stl</uri>
          </mesh>
        </geometry>
        <surface>
          <contact>
            <ode/>
          </contact>
          <friction>
            <ode>
              <mu>0.2</mu>
              <mu2>0.2</mu2>
            </ode>
          </friction>
        </surface>
      </collision>
      <collision name='servo_neck__1_fixed_joint_lump__jaw_1_collision_1'>
        <pose>-0.047554 0 -0.035941 0 -0 0</pose>
        <geometry>
          <mesh>
            <scale>0.001 0.001 0.001</scale>
            <uri>file:///workspaces/clyderos2/install/share/clyde_description/src/models/clyde_model/meshes/jaw_1.stl</uri>
          </mesh>
        </geometry>
        <surface>
          <contact>
            <ode/>
          </contact>
          <friction>
            <ode>
              <mu>0.2</mu>
              <mu2>0.2</mu2>
            </ode>
          </friction>
        </surface>
      </collision>
      <collision name='servo_neck__1_fixed_joint_lump__head__1_collision_2'>
        <pose>-0.047554 -0 -0.035941 0 -0 0</pose>
        <geometry>
          <mesh>
            <scale>0.001 0.001 0.001</scale>
            <uri>file:///workspaces/clyderos2/install/share/clyde_description/src/models/clyde_model/meshes/head__1.stl</uri>
          </mesh>
        </geometry>
        <surface>
          <contact>
            <ode/>
          </contact>
          <friction>
            <ode>
              <mu>0.2</mu>
              <mu2>0.2</mu2>
            </ode>
          </friction>
        </surface>
      </collision>
      <collision name='servo_neck__1_fixed_joint_lump__camera_link_collision_3'>
        <pose>0.018157 0.002845 0.039386 -0.328142 0.100934 -0.592231</pose>
        <geometry>
          <box>
            <size>0.01 0.01 0.01</size>
          </box>
        </geometry>
        <surface>
          <contact>
            <ode/>
          </contact>
          <friction>
            <ode/>
          </friction>
        </surface>
      </collision>
      <visual name='servo_neck__1_visual'>
        <pose>-0.047554 0 -0.035941 0 -0 0</pose>
        <geometry>
          <mesh>
            <scale>0.001 0.001 0.001</scale>
            <uri>file:///workspaces/clyderos2/install/share/clyde_description/src/models/clyde_model/meshes/servo_neck__1.stl</uri>
          </mesh>
        </geometry>
        <material>
          <ambient>39 61 51 1</ambient>
        </material>
      </visual>
      <visual name='servo_neck__1_fixed_joint_lump__jaw_1_visual_1'>
        <pose>-0.047554 0 -0.035941 0 -0 0</pose>
        <geometry>
          <mesh>
            <scale>0.001 0.001 0.001</scale>
            <uri>file:///workspaces/clyderos2/install/share/clyde_description/src/models/clyde_model/meshes/jaw_1.stl</uri>
          </mesh>
        </geometry>
        <material>
          <ambient>0 167 255 1</ambient>
        </material>
      </visual>
      <visual name='servo_neck__1_fixed_joint_lump__head__1_visual_2'>
        <pose>-0.047554 -0 -0.035941 0 -0 0</pose>
        <geometry>
          <mesh>
            <scale>0.001 0.001 0.001</scale>
            <uri>file:///workspaces/clyderos2/install/share/clyde_description/src/models/clyde_model/meshes/head__1.stl</uri>
          </mesh>
        </geometry>
        <material>
          <ambient>255 171 80 1</ambient>
        </material>
      </visual>
      <visual name='servo_neck__1_fixed_joint_lump__camera_link_visual_3'>
        <pose>0.018157 0.002845 0.039386 -0.328142 0.100934 -0.592231</pose>
        <geometry>
          <box>
            <size>0.01 0.01 0.01</size>
          </box>
        </geometry>
        <material>
          <script>
            <name>Gazebo/Red</name>
            <uri>file://media/materials/scripts/gazebo.material</uri>
          </script>
        </material>
      </visual>
      <self_collide>1</self_collide>
      <sensor name='camera' type='camera'>
        <visualize>1</visualize>
        <update_rate>10</update_rate>
        <camera>
          <horizontal_fov>1.089</horizontal_fov>
          <image>
            <format>R8G8B8</format>
            <width>640</width>
            <height>480</height>
          </image>
          <clip>
            <near>0.05</near>
            <far>8</far>
          </clip>
        </camera>
        <plugin name='camera_controller' filename='libgazebo_ros_camera.so'>
          <frame_name>camera_link_optical</frame_name>
        </plugin>
        <pose>0.018157 0.002845 0.039386 -0.328142 0.100934 -0.592231</pose>
      </sensor>
    </link>
    <static>0</static>
    <plugin name='control' filename='libgazebo_ros_control.so'/>
  </model>
</sdf>
