<?xml version="1.0" ?>
<robot name="clyde" xmlns:xacro="http://www.ros.org/wiki/xacro">

<xacro:include filename="$(find clyde_description)/src/urdf/materials.xacro" />
<xacro:include filename="$(find clyde_description)/src/urdf/clyde_simple.trans" />
<xacro:include filename="$(find clyde_description)/src/urdf/clyde_simple.gazebo" />

<xacro:macro name="box_inertia" params="m w h d">
  <inertial>
    <origin xyz="0 0 0" rpy="${pi/2} 0 ${pi/2}"/>      
    <mass value="${m}"/>
    <inertia ixx="${(m/12) * (h*h + d*d)}" ixy="0.0" ixz="0.0" iyy="${(m/12) * (w*w + d*d)}" iyz="0.0" izz="${(m/12) * (w*w + h*h)}"/>
  </inertial>
</xacro:macro>

<xacro:property name="camera_link" value="0.05" />

<link name="base_link">
  <inertial>
    <origin xyz="0.002168345924058267 0 0.02555254458454454" rpy="0 0 0"/>
    <mass value="0.01989030949409733"/>
    <inertia ixx="1.5e-05" iyy="2.4e-05" izz="3.8e-05" ixy="0.0" iyz="0.0" ixz="-0.0"/>
  </inertial>
  <visual>
    <origin xyz="0 0 0" rpy="0 0 0"/>
    <geometry>
      <mesh filename="package://clyde_description/src/meshes/base_link.stl" scale="0.001 0.001 0.001"/>
    </geometry>
    <material name="silver"/>
  </visual>
  <collision>
    <origin xyz="0 0 0" rpy="0 0 0"/>
    <geometry>
      <mesh filename="package://clyde_description/src/meshes/base_link.stl" scale="0.001 0.001 0.001"/>
    </geometry>
  </collision>
</link>

<link name="base_footprint"/>

<link name="camera_link">
  <collision>
    <origin xyz="0 0 0" rpy="0 0 0"/>
    <geometry>
  <box size="${camera_link} ${camera_link} ${camera_link}"/>
    </geometry>
  </collision>

  <visual>
    <origin xyz="0 0 0" rpy="0 0 0"/>
    <geometry>
  <box size="${camera_link} ${camera_link} ${camera_link}"/>
    </geometry>
    <material name="red"/>
  </visual>

  <inertial>
    <mass value="1e-5" />
    <origin xyz="0 0 0" rpy="0 0 0"/>
    <inertia ixx="1e-6" ixy="0" ixz="0" iyy="1e-6" iyz="0" izz="1e-6" />
  </inertial>
</link>

<joint name="camera_joint" type="fixed">
  <axis xyz="0 1 0" />
  <origin xyz="${camera_link} 0 0" rpy="-0.32814212668464987 0.10093359552132034 -0.5922309969483743"/>
  <parent link="head__1"/>
  <child link="camera_link"/>
</joint>

<link name="front__1">
  <inertial>
    <origin xyz="-0.00995696017036956 0.02800119957987551 -0.0005395302490400072" rpy="0 0 0"/>
    <mass value="0.0039123866206911126"/>
    <inertia ixx="2e-06" iyy="1e-06" izz="2e-06" ixy="0.0" iyz="-0.0" ixz="0.0"/>
  </inertial>
  <visual>
    <origin xyz="-0.061733 0.028 -0.025792" rpy="0 0 0"/>
    <geometry>
      <mesh filename="package://clyde_description/src/meshes/front__1.stl" scale="0.001 0.001 0.001"/>
    </geometry>
    <material name="silver"/>
  </visual>
  <collision>
    <origin xyz="-0.061733 0.028 -0.025792" rpy="0 0 0"/>
    <geometry>
      <mesh filename="package://clyde_description/src/meshes/front__1.stl" scale="0.001 0.001 0.001"/>
    </geometry>
  </collision>
</link>

<link name="rear__1">
  <inertial>
    <origin xyz="0.009956960170745259 -0.027998805995973614 -0.0005395302462037725" rpy="0 0 0"/>
    <mass value="0.003912386618757239"/>
    <inertia ixx="2e-06" iyy="1e-06" izz="2e-06" ixy="-0.0" iyz="-0.0" ixz="-0.0"/>
  </inertial>
  <visual>
    <origin xyz="0.061733 -0.028 -0.025792" rpy="0 0 0"/>
    <geometry>
      <mesh filename="package://clyde_description/src/meshes/rear__1.stl" scale="0.001 0.001 0.001"/>
    </geometry>
    <material name="silver"/>
  </visual>
  <collision>
    <origin xyz="0.061733 -0.028 -0.025792" rpy="0 0 0"/>
    <geometry>
      <mesh filename="package://clyde_description/src/meshes/rear__1.stl" scale="0.001 0.001 0.001"/>
    </geometry>
  </collision>
</link>

<link name="servo_rfs_1">
  <inertial>
    <origin xyz="-0.012134511463850035 0.0033276213458265785 0.007005695786782645" rpy="0 0 0"/>
    <mass value="0.016198785326804743"/>
    <inertia ixx="1e-06" iyy="1e-06" izz="1e-06" ixy="0.0" iyz="-0.0" ixz="0.0"/>
  </inertial>
  <visual>
    <origin xyz="-0.059645 0.036 -0.017875" rpy="0 0 0"/>
    <geometry>
      <mesh filename="package://clyde_description/src/meshes/servo_rfs_1.stl" scale="0.001 0.001 0.001"/>
    </geometry>
    <material name="silver"/>
  </visual>
  <collision>
    <origin xyz="-0.059645 0.036 -0.017875" rpy="0 0 0"/>
    <geometry>
      <mesh filename="package://clyde_description/src/meshes/servo_rfs_1.stl" scale="0.001 0.001 0.001"/>
    </geometry>
  </collision>
</link>

<link name="servo_rrs__1">
  <inertial>
    <origin xyz="0.012134511463850035 0.0033276213458265508 0.007005695786782652" rpy="0 0 0"/>
    <mass value="0.016198785326804747"/>
    <inertia ixx="1e-06" iyy="1e-06" izz="1e-06" ixy="-0.0" iyz="-0.0" ixz="-0.0"/>
  </inertial>
  <visual>
    <origin xyz="0.059645 0.036 -0.017875" rpy="0 0 0"/>
    <geometry>
      <mesh filename="package://clyde_description/src/meshes/servo_rrs__1.stl" scale="0.001 0.001 0.001"/>
    </geometry>
    <material name="silver"/>
  </visual>
  <collision>
    <origin xyz="0.059645 0.036 -0.017875" rpy="0 0 0"/>
    <geometry>
      <mesh filename="package://clyde_description/src/meshes/servo_rrs__1.stl" scale="0.001 0.001 0.001"/>
    </geometry>
  </collision>
</link>

<link name="c_neck__1">
  <inertial>
    <origin xyz="0.0003476160573467474 8.689791074277334e-16 0.0015392691836189978" rpy="0 0 0"/>
    <mass value="0.0002786420162302464"/>
    <inertia ixx="0.0" iyy="0.0" izz="0.0" ixy="0.0" iyz="-0.0" ixz="0.0"/>
  </inertial>
  <visual>
    <origin xyz="-0.044904 -0.0 -0.031351" rpy="0 0 0"/>
    <geometry>
      <mesh filename="package://clyde_description/src/meshes/c_neck__1.stl" scale="0.001 0.001 0.001"/>
    </geometry>
    <material name="silver"/>
  </visual>
  <collision>
    <origin xyz="-0.044904 -0.0 -0.031351" rpy="0 0 0"/>
    <geometry>
      <mesh filename="package://clyde_description/src/meshes/c_neck__1.stl" scale="0.001 0.001 0.001"/>
    </geometry>
  </collision>
</link>

<link name="head__1">
  <inertial>
    <origin xyz="0.01773367569221658 0.010875428717563109 0.005303020015208416" rpy="0 0 0"/>
    <mass value="0.0047175875144439645"/>
    <inertia ixx="1e-06" iyy="1e-06" izz="1e-06" ixy="0.0" iyz="-0.0" ixz="0.0"/>
  </inertial>
  <visual>
    <origin xyz="-0.055711 0.017155 -0.060327" rpy="0 0 0"/>
    <geometry>
      <mesh filename="package://clyde_description/src/meshes/head__1.stl" scale="0.001 0.001 0.001"/>
    </geometry>
    <material name="silver"/>
  </visual>
  <collision>
    <origin xyz="-0.055711 0.017155 -0.060327" rpy="0 0 0"/>
    <geometry>
      <mesh filename="package://clyde_description/src/meshes/head__1.stl" scale="0.001 0.001 0.001"/>
    </geometry>
  </collision>
</link>

<link name="jaw_1">
  <inertial>
    <origin xyz="-0.0009535400770716435 0.0073141018408541866 0.015990572203006634" rpy="0 0 0"/>
    <mass value="0.00390701419929372"/>
    <inertia ixx="1e-06" iyy="1e-06" izz="1e-06" ixy="0.0" iyz="0.0" ixz="0.0"/>
  </inertial>
  <visual>
    <origin xyz="-0.06445 0.012925 -0.034027" rpy="0 0 0"/>
    <geometry>
      <mesh filename="package://clyde_description/src/meshes/jaw_1.stl" scale="0.001 0.001 0.001"/>
    </geometry>
    <material name="silver"/>
  </visual>
  <collision>
    <origin xyz="-0.06445 0.012925 -0.034027" rpy="0 0 0"/>
    <geometry>
      <mesh filename="package://clyde_description/src/meshes/jaw_1.stl" scale="0.001 0.001 0.001"/>
    </geometry>
  </collision>
</link>

<link name="tho_rf__1">
  <inertial>
    <origin xyz="-0.020399619281867152 -1.772774812243416e-05 -0.0054647510340394435" rpy="0 0 0"/>
    <mass value="0.0016124935043948178"/>
    <inertia ixx="0.0" iyy="0.0" izz="0.0" ixy="-0.0" iyz="-0.0" ixz="-0.0"/>
  </inertial>
  <visual>
    <origin xyz="-0.038977 0.050355 -0.018377" rpy="0 0 0"/>
    <geometry>
      <mesh filename="package://clyde_description/src/meshes/tho_rf__1.stl" scale="0.001 0.001 0.001"/>
    </geometry>
    <material name="silver"/>
  </visual>
  <collision>
    <origin xyz="-0.038977 0.050355 -0.018377" rpy="0 0 0"/>
    <geometry>
      <mesh filename="package://clyde_description/src/meshes/tho_rf__1.stl" scale="0.001 0.001 0.001"/>
    </geometry>
  </collision>
</link>

<link name="servo_neck__1">
  <inertial>
    <origin xyz="0.01000501101063378 -0.0036770959380430985 0.008458014805728817" rpy="0 0 0"/>
    <mass value="0.016198785326804754"/>
    <inertia ixx="1e-06" iyy="1e-06" izz="1e-06" ixy="0.0" iyz="-0.0" ixz="-0.0"/>
  </inertial>
  <visual>
    <origin xyz="-0.047554 -0.0 -0.035941" rpy="0 0 0"/>
    <geometry>
      <mesh filename="package://clyde_description/src/meshes/servo_neck__1.stl" scale="0.001 0.001 0.001"/>
    </geometry>
    <material name="silver"/>
  </visual>
  <collision>
    <origin xyz="-0.047554 -0.0 -0.035941" rpy="0 0 0"/>
    <geometry>
      <mesh filename="package://clyde_description/src/meshes/servo_neck__1.stl" scale="0.001 0.001 0.001"/>
    </geometry>
  </collision>
</link>

<link name="tube__1">
  <inertial>
    <origin xyz="0.0011153307229088694 0.005350015413290346 -0.004241660835567474" rpy="0 0 0"/>
    <mass value="0.0008476319886892588"/>
    <inertia ixx="0.0" iyy="0.0" izz="0.0" ixy="-0.0" iyz="-0.0" ixz="-0.0"/>
  </inertial>
  <visual>
    <origin xyz="-0.02915 0.052607 -0.02028" rpy="0 0 0"/>
    <geometry>
      <mesh filename="package://clyde_description/src/meshes/tube__1.stl" scale="0.001 0.001 0.001"/>
    </geometry>
    <material name="silver"/>
  </visual>
  <collision>
    <origin xyz="-0.02915 0.052607 -0.02028" rpy="0 0 0"/>
    <geometry>
      <mesh filename="package://clyde_description/src/meshes/tube__1.stl" scale="0.001 0.001 0.001"/>
    </geometry>
  </collision>
</link>

<link name="th_rf_1">
  <inertial>
    <origin xyz="-0.01050527468812052 0.0005245346031438683 -0.0028130983482547826" rpy="0 0 0"/>
    <mass value="0.0016124994656611404"/>
    <inertia ixx="0.0" iyy="0.0" izz="0.0" ixy="-0.0" iyz="-0.0" ixz="-0.0"/>
  </inertial>
  <visual>
    <origin xyz="-0.0525 0.0508 -0.022" rpy="0 0 0"/>
    <geometry>
      <mesh filename="package://clyde_description/src/meshes/th_rf_1.stl" scale="0.001 0.001 0.001"/>
    </geometry>
    <material name="silver"/>
  </visual>
  <collision>
    <origin xyz="-0.0525 0.0508 -0.022" rpy="0 0 0"/>
    <geometry>
      <mesh filename="package://clyde_description/src/meshes/th_rf_1.stl" scale="0.001 0.001 0.001"/>
    </geometry>
  </collision>
</link>

<link name="c_thorf_1">
  <inertial>
    <origin xyz="0.0004222776002216107 0.003991736806568551 0.00011331940655908042" rpy="0 0 0"/>
    <mass value="0.0003202445573374636"/>
    <inertia ixx="0.0" iyy="0.0" izz="0.0" ixy="0.0" iyz="0.0" ixz="-0.0"/>
  </inertial>
  <visual>
    <origin xyz="-0.008067 0.054937 -0.010094" rpy="0 0 0"/>
    <geometry>
      <mesh filename="package://clyde_description/src/meshes/c_thorf_1.stl" scale="0.001 0.001 0.001"/>
    </geometry>
    <material name="silver"/>
  </visual>
  <collision>
    <origin xyz="-0.008067 0.054937 -0.010094" rpy="0 0 0"/>
    <geometry>
      <mesh filename="package://clyde_description/src/meshes/c_thorf_1.stl" scale="0.001 0.001 0.001"/>
    </geometry>
  </collision>
</link>

<link name="servo_lfs_1">
  <inertial>
    <origin xyz="-0.012134511463850035 -0.0033276213458265855 0.007005695786782638" rpy="0 0 0"/>
    <mass value="0.016198785326804747"/>
    <inertia ixx="1e-06" iyy="1e-06" izz="1e-06" ixy="-0.0" iyz="0.0" ixz="0.0"/>
  </inertial>
  <visual>
    <origin xyz="-0.059645 -0.036 -0.017875" rpy="0 0 0"/>
    <geometry>
      <mesh filename="package://clyde_description/src/meshes/servo_lfs_1.stl" scale="0.001 0.001 0.001"/>
    </geometry>
    <material name="silver"/>
  </visual>
  <collision>
    <origin xyz="-0.059645 -0.036 -0.017875" rpy="0 0 0"/>
    <geometry>
      <mesh filename="package://clyde_description/src/meshes/servo_lfs_1.stl" scale="0.001 0.001 0.001"/>
    </geometry>
  </collision>
</link>

<link name="servo_lrs__1">
  <inertial>
    <origin xyz="0.012134511463850021 -0.0033276213458265577 0.007005695786782652" rpy="0 0 0"/>
    <mass value="0.006359523128301122"/>
    <inertia ixx="0.0" iyy="0.0" izz="0.0" ixy="0.0" iyz="0.0" ixz="-0.0"/>
  </inertial>
  <visual>
    <origin xyz="0.059645 -0.036 -0.017875" rpy="0 0 0"/>
    <geometry>
      <mesh filename="package://clyde_description/src/meshes/servo_lrs__1.stl" scale="0.001 0.001 0.001"/>
    </geometry>
    <material name="silver"/>
  </visual>
  <collision>
    <origin xyz="0.059645 -0.036 -0.017875" rpy="0 0 0"/>
    <geometry>
      <mesh filename="package://clyde_description/src/meshes/servo_lrs__1.stl" scale="0.001 0.001 0.001"/>
    </geometry>
  </collision>
</link>

<link name="c_thrf__1">
  <inertial>
    <origin xyz="-0.00042182341489750697 -0.00035936825370828235 -0.00011295581414910716" rpy="0 0 0"/>
    <mass value="0.00032023395581114655"/>
    <inertia ixx="0.0" iyy="0.0" izz="0.0" ixy="-0.0" iyz="-0.0" ixz="-0.0"/>
  </inertial>
  <visual>
    <origin xyz="-0.0525 0.0485 -0.022" rpy="0 0 0"/>
    <geometry>
      <mesh filename="package://clyde_description/src/meshes/c_thrf__1.stl" scale="0.001 0.001 0.001"/>
    </geometry>
    <material name="silver"/>
  </visual>
  <collision>
    <origin xyz="-0.0525 0.0485 -0.022" rpy="0 0 0"/>
    <geometry>
      <mesh filename="package://clyde_description/src/meshes/c_thrf__1.stl" scale="0.001 0.001 0.001"/>
    </geometry>
  </collision>
</link>

<link name="shank_rf_1">
  <inertial>
    <origin xyz="0.02914718937367968 0.005499606726463185 -0.0015596735350774712" rpy="0 0 0"/>
    <mass value="0.0023337750085593027"/>
    <inertia ixx="0.0" iyy="1e-06" izz="1e-06" ixy="-0.0" iyz="-0.0" ixz="0.0"/>
  </inertial>
  <visual>
    <origin xyz="0.000151 0.03958 -0.010813" rpy="0 0 0"/>
    <geometry>
      <mesh filename="package://clyde_description/src/meshes/shank_rf_1.stl" scale="0.001 0.001 0.001"/>
    </geometry>
    <material name="silver"/>
  </visual>
  <collision>
    <origin xyz="0.000151 0.03958 -0.010813" rpy="0 0 0"/>
    <geometry>
      <mesh filename="package://clyde_description/src/meshes/shank_rf_1.stl" scale="0.001 0.001 0.001"/>
    </geometry>
  </collision>
</link>

<link name="servos_rf_1">
  <inertial>
    <origin xyz="0.005739879729918549 0.012327652284320013 -0.0005018144365687635" rpy="0 0 0"/>
    <mass value="0.016198785326804754"/>
    <inertia ixx="1e-06" iyy="1e-06" izz="1e-06" ixy="-0.0" iyz="0.0" ixz="0.0"/>
  </inertial>
  <visual>
    <origin xyz="-0.008067 0.04708 -0.010094" rpy="0 0 0"/>
    <geometry>
      <mesh filename="package://clyde_description/src/meshes/servos_rf_1.stl" scale="0.001 0.001 0.001"/>
    </geometry>
    <material name="silver"/>
  </visual>
  <collision>
    <origin xyz="-0.008067 0.04708 -0.010094" rpy="0 0 0"/>
    <geometry>
      <mesh filename="package://clyde_description/src/meshes/servos_rf_1.stl" scale="0.001 0.001 0.001"/>
    </geometry>
  </collision>
</link>

<link name="tho_rr_1">
  <inertial>
    <origin xyz="-0.020408725212817044 -1.7727748122586817e-05 -0.005464751034039705" rpy="0 0 0"/>
    <mass value="0.0016124935043948343"/>
    <inertia ixx="0.0" iyy="0.0" izz="0.0" ixy="-0.0" iyz="-0.0" ixz="-0.0"/>
  </inertial>
  <visual>
    <origin xyz="0.066023 0.050355 -0.018377" rpy="0 0 0"/>
    <geometry>
      <mesh filename="package://clyde_description/src/meshes/tho_rr_1.stl" scale="0.001 0.001 0.001"/>
    </geometry>
    <material name="silver"/>
  </visual>
  <collision>
    <origin xyz="0.066023 0.050355 -0.018377" rpy="0 0 0"/>
    <geometry>
      <mesh filename="package://clyde_description/src/meshes/tho_rr_1.stl" scale="0.001 0.001 0.001"/>
    </geometry>
  </collision>
</link>

<link name="tube_rr_1">
  <inertial>
    <origin xyz="0.0011068997341559944 0.005350055560855632 -0.004241660835570902" rpy="0 0 0"/>
    <mass value="0.0008476319886892679"/>
    <inertia ixx="0.0" iyy="0.0" izz="0.0" ixy="-0.0" iyz="-0.0" ixz="-0.0"/>
  </inertial>
  <visual>
    <origin xyz="0.07585 0.052607 -0.02028" rpy="0 0 0"/>
    <geometry>
      <mesh filename="package://clyde_description/src/meshes/tube_rr_1.stl" scale="0.001 0.001 0.001"/>
    </geometry>
    <material name="silver"/>
  </visual>
  <collision>
    <origin xyz="0.07585 0.052607 -0.02028" rpy="0 0 0"/>
    <geometry>
      <mesh filename="package://clyde_description/src/meshes/tube_rr_1.stl" scale="0.001 0.001 0.001"/>
    </geometry>
  </collision>
</link>

<link name="th_rr_1">
  <inertial>
    <origin xyz="-0.010514274143062795 0.000524534603143785 -0.0028130983482549457" rpy="0 0 0"/>
    <mass value="0.0016124994656611426"/>
    <inertia ixx="0.0" iyy="0.0" izz="0.0" ixy="-0.0" iyz="-0.0" ixz="-0.0"/>
  </inertial>
  <visual>
    <origin xyz="0.0525 0.0508 -0.022" rpy="0 0 0"/>
    <geometry>
      <mesh filename="package://clyde_description/src/meshes/th_rr_1.stl" scale="0.001 0.001 0.001"/>
    </geometry>
    <material name="silver"/>
  </visual>
  <collision>
    <origin xyz="0.0525 0.0508 -0.022" rpy="0 0 0"/>
    <geometry>
      <mesh filename="package://clyde_description/src/meshes/th_rr_1.stl" scale="0.001 0.001 0.001"/>
    </geometry>
  </collision>
</link>

<link name="c_thorr_1">
  <inertial>
    <origin xyz="0.00042227774781423977 0.003991708659830846 0.0001133224303485527" rpy="0 0 0"/>
    <mass value="0.00032024480790842274"/>
    <inertia ixx="0.0" iyy="0.0" izz="0.0" ixy="0.0" iyz="0.0" ixz="-0.0"/>
  </inertial>
  <visual>
    <origin xyz="0.096933 0.054937 -0.010094" rpy="0 0 0"/>
    <geometry>
      <mesh filename="package://clyde_description/src/meshes/c_thorr_1.stl" scale="0.001 0.001 0.001"/>
    </geometry>
    <material name="silver"/>
  </visual>
  <collision>
    <origin xyz="0.096933 0.054937 -0.010094" rpy="0 0 0"/>
    <geometry>
      <mesh filename="package://clyde_description/src/meshes/c_thorr_1.stl" scale="0.001 0.001 0.001"/>
    </geometry>
  </collision>
</link>

<link name="shank_rr_1">
  <inertial>
    <origin xyz="0.029146293610457355 0.005499606726463067 -0.001559673535077303" rpy="0 0 0"/>
    <mass value="0.0023337750085593014"/>
    <inertia ixx="0.0" iyy="1e-06" izz="1e-06" ixy="0.0" iyz="-0.0" ixz="0.0"/>
  </inertial>
  <visual>
    <origin xyz="0.105151 0.03958 -0.010813" rpy="0 0 0"/>
    <geometry>
      <mesh filename="package://clyde_description/src/meshes/shank_rr_1.stl" scale="0.001 0.001 0.001"/>
    </geometry>
    <material name="silver"/>
  </visual>
  <collision>
    <origin xyz="0.105151 0.03958 -0.010813" rpy="0 0 0"/>
    <geometry>
      <mesh filename="package://clyde_description/src/meshes/shank_rr_1.stl" scale="0.001 0.001 0.001"/>
    </geometry>
  </collision>
</link>

<link name="c_thrr_1">
  <inertial>
    <origin xyz="-0.0004218234148973682 -0.0003593682537082407 -0.00011295581414910022" rpy="0 0 0"/>
    <mass value="0.00032023395581114384"/>
    <inertia ixx="0.0" iyy="0.0" izz="0.0" ixy="-0.0" iyz="-0.0" ixz="-0.0"/>
  </inertial>
  <visual>
    <origin xyz="0.0525 0.0485 -0.022" rpy="0 0 0"/>
    <geometry>
      <mesh filename="package://clyde_description/src/meshes/c_thrr_1.stl" scale="0.001 0.001 0.001"/>
    </geometry>
    <material name="silver"/>
  </visual>
  <collision>
    <origin xyz="0.0525 0.0485 -0.022" rpy="0 0 0"/>
    <geometry>
      <mesh filename="package://clyde_description/src/meshes/c_thrr_1.stl" scale="0.001 0.001 0.001"/>
    </geometry>
  </collision>
</link>

<link name="servos_rr_1">
  <inertial>
    <origin xyz="0.005739879729918462 0.01232765228431986 -0.0005018144365687583" rpy="0 0 0"/>
    <mass value="0.01619878532680476"/>
    <inertia ixx="1e-06" iyy="1e-06" izz="1e-06" ixy="-0.0" iyz="0.0" ixz="0.0"/>
  </inertial>
  <visual>
    <origin xyz="0.096933 0.04708 -0.010094" rpy="0 0 0"/>
    <geometry>
      <mesh filename="package://clyde_description/src/meshes/servos_rr_1.stl" scale="0.001 0.001 0.001"/>
    </geometry>
    <material name="silver"/>
  </visual>
  <collision>
    <origin xyz="0.096933 0.04708 -0.010094" rpy="0 0 0"/>
    <geometry>
      <mesh filename="package://clyde_description/src/meshes/servos_rr_1.stl" scale="0.001 0.001 0.001"/>
    </geometry>
  </collision>
</link>

<link name="tho_lf_1">
  <inertial>
    <origin xyz="-0.020399618230848855 1.7728746515156824e-05 -0.005464752801987643" rpy="0 0 0"/>
    <mass value="0.001612494755128593"/>
    <inertia ixx="0.0" iyy="0.0" izz="0.0" ixy="0.0" iyz="0.0" ixz="-0.0"/>
  </inertial>
  <visual>
    <origin xyz="-0.038977 -0.050355 -0.018377" rpy="0 0 0"/>
    <geometry>
      <mesh filename="package://clyde_description/src/meshes/tho_lf_1.stl" scale="0.001 0.001 0.001"/>
    </geometry>
    <material name="silver"/>
  </visual>
  <collision>
    <origin xyz="-0.038977 -0.050355 -0.018377" rpy="0 0 0"/>
    <geometry>
      <mesh filename="package://clyde_description/src/meshes/tho_lf_1.stl" scale="0.001 0.001 0.001"/>
    </geometry>
  </collision>
</link>

<link name="tube_lf_1">
  <inertial>
    <origin xyz="0.001115432542211546 -0.005350009270953589 -0.004241568374152932" rpy="0 0 0"/>
    <mass value="0.0008476239616137593"/>
    <inertia ixx="0.0" iyy="0.0" izz="0.0" ixy="0.0" iyz="0.0" ixz="-0.0"/>
  </inertial>
  <visual>
    <origin xyz="-0.02915 -0.052607 -0.02028" rpy="0 0 0"/>
    <geometry>
      <mesh filename="package://clyde_description/src/meshes/tube_lf_1.stl" scale="0.001 0.001 0.001"/>
    </geometry>
    <material name="silver"/>
  </visual>
  <collision>
    <origin xyz="-0.02915 -0.052607 -0.02028" rpy="0 0 0"/>
    <geometry>
      <mesh filename="package://clyde_description/src/meshes/tube_lf_1.stl" scale="0.001 0.001 0.001"/>
    </geometry>
  </collision>
</link>

<link name="th_lf_1">
  <inertial>
    <origin xyz="-0.010505273662324732 -0.0005245335979957022 -0.002813100120197417" rpy="0 0 0"/>
    <mass value="0.001612498214964083"/>
    <inertia ixx="0.0" iyy="0.0" izz="0.0" ixy="0.0" iyz="0.0" ixz="-0.0"/>
  </inertial>
  <visual>
    <origin xyz="-0.0525 -0.0508 -0.022" rpy="0 0 0"/>
    <geometry>
      <mesh filename="package://clyde_description/src/meshes/th_lf_1.stl" scale="0.001 0.001 0.001"/>
    </geometry>
    <material name="silver"/>
  </visual>
  <collision>
    <origin xyz="-0.0525 -0.0508 -0.022" rpy="0 0 0"/>
    <geometry>
      <mesh filename="package://clyde_description/src/meshes/th_lf_1.stl" scale="0.001 0.001 0.001"/>
    </geometry>
  </collision>
</link>

<link name="c_tholf_1">
  <inertial>
    <origin xyz="0.0004222278652181253 -0.003991757543920296 0.00011334144666966424" rpy="0 0 0"/>
    <mass value="0.0003202330738267581"/>
    <inertia ixx="0.0" iyy="0.0" izz="0.0" ixy="-0.0" iyz="-0.0" ixz="-0.0"/>
  </inertial>
  <visual>
    <origin xyz="-0.008067 -0.054937 -0.010094" rpy="0 0 0"/>
    <geometry>
      <mesh filename="package://clyde_description/src/meshes/c_tholf_1.stl" scale="0.001 0.001 0.001"/>
    </geometry>
    <material name="silver"/>
  </visual>
  <collision>
    <origin xyz="-0.008067 -0.054937 -0.010094" rpy="0 0 0"/>
    <geometry>
      <mesh filename="package://clyde_description/src/meshes/c_tholf_1.stl" scale="0.001 0.001 0.001"/>
    </geometry>
  </collision>
</link>

<link name="shank_lf_1">
  <inertial>
    <origin xyz="0.02914721079288764 -0.005501605881848795 -0.001559675747550105" rpy="0 0 0"/>
    <mass value="0.0023337769575448"/>
    <inertia ixx="0.0" iyy="1e-06" izz="1e-06" ixy="0.0" iyz="0.0" ixz="0.0"/>
  </inertial>
  <visual>
    <origin xyz="0.000151 -0.039582 -0.010813" rpy="0 0 0"/>
    <geometry>
      <mesh filename="package://clyde_description/src/meshes/shank_lf_1.stl" scale="0.001 0.001 0.001"/>
    </geometry>
    <material name="silver"/>
  </visual>
  <collision>
    <origin xyz="0.000151 -0.039582 -0.010813" rpy="0 0 0"/>
    <geometry>
      <mesh filename="package://clyde_description/src/meshes/shank_lf_1.stl" scale="0.001 0.001 0.001"/>
    </geometry>
  </collision>
</link>

<link name="c_thlf_1">
  <inertial>
    <origin xyz="-0.00042183741166247624 0.00035936726829538523 -0.00011295723467287175" rpy="0 0 0"/>
    <mass value="0.00032023478629957983"/>
    <inertia ixx="0.0" iyy="0.0" izz="0.0" ixy="0.0" iyz="0.0" ixz="-0.0"/>
  </inertial>
  <visual>
    <origin xyz="-0.0525 -0.0485 -0.022" rpy="0 0 0"/>
    <geometry>
      <mesh filename="package://clyde_description/src/meshes/c_thlf_1.stl" scale="0.001 0.001 0.001"/>
    </geometry>
    <material name="silver"/>
  </visual>
  <collision>
    <origin xyz="-0.0525 -0.0485 -0.022" rpy="0 0 0"/>
    <geometry>
      <mesh filename="package://clyde_description/src/meshes/c_thlf_1.stl" scale="0.001 0.001 0.001"/>
    </geometry>
  </collision>
</link>

<link name="servos_lf_1">
  <inertial>
    <origin xyz="0.0057398797299185594 -0.012327652284320006 -0.0005018144365687965" rpy="0 0 0"/>
    <mass value="0.016198785326804747"/>
    <inertia ixx="1e-06" iyy="1e-06" izz="1e-06" ixy="0.0" iyz="-0.0" ixz="0.0"/>
  </inertial>
  <visual>
    <origin xyz="-0.008067 -0.04708 -0.010094" rpy="0 0 0"/>
    <geometry>
      <mesh filename="package://clyde_description/src/meshes/servos_lf_1.stl" scale="0.001 0.001 0.001"/>
    </geometry>
    <material name="silver"/>
  </visual>
  <collision>
    <origin xyz="-0.008067 -0.04708 -0.010094" rpy="0 0 0"/>
    <geometry>
      <mesh filename="package://clyde_description/src/meshes/servos_lf_1.stl" scale="0.001 0.001 0.001"/>
    </geometry>
  </collision>
</link>

<link name="tho_lr_1">
  <inertial>
    <origin xyz="-0.02040872415473581 1.5728569829849548e-05 -0.00546475280198775" rpy="0 0 0"/>
    <mass value="0.0016124947551285935"/>
    <inertia ixx="0.0" iyy="0.0" izz="0.0" ixy="0.0" iyz="0.0" ixz="-0.0"/>
  </inertial>
  <visual>
    <origin xyz="0.066023 -0.050357 -0.018377" rpy="0 0 0"/>
    <geometry>
      <mesh filename="package://clyde_description/src/meshes/tho_lr_1.stl" scale="0.001 0.001 0.001"/>
    </geometry>
    <material name="silver"/>
  </visual>
  <collision>
    <origin xyz="0.066023 -0.050357 -0.018377" rpy="0 0 0"/>
    <geometry>
      <mesh filename="package://clyde_description/src/meshes/tho_lr_1.stl" scale="0.001 0.001 0.001"/>
    </geometry>
  </collision>
</link>

<link name="tube_lr_1">
  <inertial>
    <origin xyz="0.0011069988135060799 -0.00535200943454444 -0.004241568724363105" rpy="0 0 0"/>
    <mass value="0.0008476239616137176"/>
    <inertia ixx="0.0" iyy="0.0" izz="0.0" ixy="0.0" iyz="0.0" ixz="-0.0"/>
  </inertial>
  <visual>
    <origin xyz="0.07585 -0.052609 -0.02028" rpy="0 0 0"/>
    <geometry>
      <mesh filename="package://clyde_description/src/meshes/tube_lr_1.stl" scale="0.001 0.001 0.001"/>
    </geometry>
    <material name="silver"/>
  </visual>
  <collision>
    <origin xyz="0.07585 -0.052609 -0.02028" rpy="0 0 0"/>
    <geometry>
      <mesh filename="package://clyde_description/src/meshes/tube_lr_1.stl" scale="0.001 0.001 0.001"/>
    </geometry>
  </collision>
</link>

<link name="th_lr__1">
  <inertial>
    <origin xyz="-0.010514273124247346 -0.0005265337726153632 -0.0028131001201973233" rpy="0 0 0"/>
    <mass value="0.0016124982149641033"/>
    <inertia ixx="0.0" iyy="0.0" izz="0.0" ixy="0.0" iyz="0.0" ixz="-0.0"/>
  </inertial>
  <visual>
    <origin xyz="0.0525 -0.050802 -0.022" rpy="0 0 0"/>
    <geometry>
      <mesh filename="package://clyde_description/src/meshes/th_lr__1.stl" scale="0.001 0.001 0.001"/>
    </geometry>
    <material name="silver"/>
  </visual>
  <collision>
    <origin xyz="0.0525 -0.050802 -0.022" rpy="0 0 0"/>
    <geometry>
      <mesh filename="package://clyde_description/src/meshes/th_lr__1.stl" scale="0.001 0.001 0.001"/>
    </geometry>
  </collision>
</link>

<link name="c_tholr__1">
  <inertial>
    <origin xyz="0.0004222276405440456 -0.003993730098197278 0.00011333762429869935" rpy="0 0 0"/>
    <mass value="0.00032023271018070503"/>
    <inertia ixx="0.0" iyy="0.0" izz="0.0" ixy="-0.0" iyz="-0.0" ixz="-0.0"/>
  </inertial>
  <visual>
    <origin xyz="0.096933 -0.054939 -0.010094" rpy="0 0 0"/>
    <geometry>
      <mesh filename="package://clyde_description/src/meshes/c_tholr__1.stl" scale="0.001 0.001 0.001"/>
    </geometry>
    <material name="silver"/>
  </visual>
  <collision>
    <origin xyz="0.096933 -0.054939 -0.010094" rpy="0 0 0"/>
    <geometry>
      <mesh filename="package://clyde_description/src/meshes/c_tholr__1.stl" scale="0.001 0.001 0.001"/>
    </geometry>
  </collision>
</link>

<link name="shank_lr_1">
  <inertial>
    <origin xyz="0.02914631503041326 -0.005501605881848684 -0.001559675747549909" rpy="0 0 0"/>
    <mass value="0.002333776957544798"/>
    <inertia ixx="0.0" iyy="1e-06" izz="1e-06" ixy="-0.0" iyz="0.0" ixz="0.0"/>
  </inertial>
  <visual>
    <origin xyz="0.105151 -0.039582 -0.010813" rpy="0 0 0"/>
    <geometry>
      <mesh filename="package://clyde_description/src/meshes/shank_lr_1.stl" scale="0.001 0.001 0.001"/>
    </geometry>
    <material name="silver"/>
  </visual>
  <collision>
    <origin xyz="0.105151 -0.039582 -0.010813" rpy="0 0 0"/>
    <geometry>
      <mesh filename="package://clyde_description/src/meshes/shank_lr_1.stl" scale="0.001 0.001 0.001"/>
    </geometry>
  </collision>
</link>

<link name="c_thlr_1">
  <inertial>
    <origin xyz="-0.0004218374116626705 0.00035936726829547544 -0.0001129572346727746" rpy="0 0 0"/>
    <mass value="0.00032023478629957365"/>
    <inertia ixx="0.0" iyy="0.0" izz="0.0" ixy="0.0" iyz="0.0" ixz="-0.0"/>
  </inertial>
  <visual>
    <origin xyz="0.0525 -0.0485 -0.022" rpy="0 0 0"/>
    <geometry>
      <mesh filename="package://clyde_description/src/meshes/c_thlr_1.stl" scale="0.001 0.001 0.001"/>
    </geometry>
    <material name="silver"/>
  </visual>
  <collision>
    <origin xyz="0.0525 -0.0485 -0.022" rpy="0 0 0"/>
    <geometry>
      <mesh filename="package://clyde_description/src/meshes/c_thlr_1.stl" scale="0.001 0.001 0.001"/>
    </geometry>
  </collision>
</link>

<link name="servos_lr_1">
  <inertial>
    <origin xyz="0.005739879729918365 -0.012329652284319856 -0.00050181443656876" rpy="0 0 0"/>
    <mass value="0.016198785326804757"/>
    <inertia ixx="1e-06" iyy="1e-06" izz="1e-06" ixy="0.0" iyz="-0.0" ixz="0.0"/>
  </inertial>
  <visual>
    <origin xyz="0.096933 -0.047082 -0.010094" rpy="0 0 0"/>
    <geometry>
      <mesh filename="package://clyde_description/src/meshes/servos_lr_1.stl" scale="0.001 0.001 0.001"/>
    </geometry>
    <material name="silver"/>
  </visual>
  <collision>
    <origin xyz="0.096933 -0.047082 -0.010094" rpy="0 0 0"/>
    <geometry>
      <mesh filename="package://clyde_description/src/meshes/servos_lr_1.stl" scale="0.001 0.001 0.001"/>
    </geometry>
  </collision>
</link>

<link name="cover_1">
  <inertial>
    <origin xyz="-0.010740282241190646 0.0310061705224458 0.011579088374725328" rpy="0 0 0"/>
    <mass value="0.01145258010304466"/>
    <inertia ixx="5e-06" iyy="1.1e-05" izz="1.5e-05" ixy="0.0" iyz="0.0" ixz="1e-06"/>
  </inertial>
  <visual>
    <origin xyz="0.0 0.031 -0.030939" rpy="0 0 0"/>
    <geometry>
      <mesh filename="package://clyde_description/src/meshes/cover_1.stl" scale="0.001 0.001 0.001"/>
    </geometry>
    <material name="silver"/>
  </visual>
  <collision>
    <origin xyz="0.0 0.031 -0.030939" rpy="0 0 0"/>
    <geometry>
      <mesh filename="package://clyde_description/src/meshes/cover_1.stl" scale="0.001 0.001 0.001"/>
    </geometry>
  </collision>
</link>

<link name="battery_1">
  <inertial>
    <origin xyz="0.021876636754834252 -8.405303268755637e-05 -0.006111435741139797" rpy="0 0 0"/>
    <mass value="0.013594087959397514"/>
    <inertia ixx="2e-06" iyy="1e-05" izz="1.2e-05" ixy="-0.0" iyz="-0.0" ixz="0.0"/>
  </inertial>
  <visual>
    <origin xyz="0.01725 -0.0 -0.023892" rpy="0 0 0"/>
    <geometry>
      <mesh filename="package://clyde_description/src/meshes/battery_1.stl" scale="0.001 0.001 0.001"/>
    </geometry>
    <material name="silver"/>
  </visual>
  <collision>
    <origin xyz="0.01725 -0.0 -0.023892" rpy="0 0 0"/>
    <geometry>
      <mesh filename="package://clyde_description/src/meshes/battery_1.stl" scale="0.001 0.001 0.001"/>
    </geometry>
  </collision>
</link>

<link name="imu_link">
  <visual>
    <geometry>
      <box size="0.01 0.01 0.01"/>
    </geometry>
  </visual>

  <collision>
    <geometry>
      <box size="0.01 0.01 0.01"/>
    </geometry>
  </collision>

  <xacro:box_inertia m="0.1" w="0.01" d="0.01" h="0.01"/>
</link>

<joint name="base_joint" type="fixed">
  <parent link="base_footprint"/>
  <child link="base_link"/>
  <origin xyz="0.0 0.0 0.0" rpy="0 0 0"/>
</joint>

<joint name="Rigid 1" type="fixed">
  <origin xyz="0.061733 -0.028 0.025792" rpy="0 0 0"/>
  <parent link="base_link"/>
  <child link="front__1"/>
</joint>

<joint name="Rigid 2" type="fixed">
  <origin xyz="-0.061733 0.028 0.025792" rpy="0 0 0"/>
  <parent link="base_link"/>
  <child link="rear__1"/>
</joint>

<joint name="Rigid 3" type="fixed">
  <origin xyz="0.059645 -0.036 0.017875" rpy="0 0 0"/>
  <parent link="base_link"/>
  <child link="servo_rfs_1"/>
</joint>

<joint name="Rigid 5" type="fixed">
  <origin xyz="-0.059645 -0.036 0.017875" rpy="0 0 0"/>
  <parent link="base_link"/>
  <child link="servo_rrs__1"/>
</joint>

<joint name="Rigid 7" type="fixed">
  <origin xyz="0.044904 0.0 0.031351" rpy="0 0 0"/>
  <parent link="base_link"/>
  <child link="c_neck__1"/>
</joint>

<joint name="Rigid 8" type="fixed">
  <origin xyz="-0.008739 -0.00423 0.0263" rpy="0 0 0"/>
  <parent link="jaw_1"/>
  <child link="head__1"/>
</joint>  

<joint name="Rigid 9" type="fixed">
  <origin xyz="0.016896 -0.012925 -0.001914" rpy="0 0 0"/>
  <parent link="servo_neck__1"/>
  <child link="jaw_1"/>
</joint>

<joint name="Rigid 10" type="fixed">
  <origin xyz="-0.013523 0.000445 -0.003623" rpy="0 0 0"/>
  <parent link="th_rf_1"/>
  <child link="tho_rf__1"/>
</joint>

<joint name="neck_joint" type="continuous">
  <origin xyz="0.00265 0.0 0.00459" rpy="0.32814212668464987 -0.10093359552132034 0.5922309969483743"/>
  <parent link="c_neck__1"/>
  <child link="servo_neck__1"/>
  <axis xyz="-0.5 -0.0 -0.866025"/>
</joint>

<joint name="Rigid 12" type="fixed">
  <origin xyz="-0.02335 -0.001807 -0.00172" rpy="0 0 0"/>
  <parent link="th_rf_1"/>
  <child link="tube__1"/>
</joint>

<joint name="Rigid 13" type="fixed">
  <origin xyz="0.0 -0.0023 0.0" rpy="0 0 0"/>
  <parent link="c_thrf__1"/>
  <child link="th_rf_1"/>
</joint>

<joint name="Rigid 14" type="fixed">
  <origin xyz="-0.03091 -0.004582 -0.008283" rpy="0 0 0"/>
  <parent link="tho_rf__1"/>
  <child link="c_thorf_1"/>
</joint>

<joint name="Rigid 4" type="fixed">
  <origin xyz="0.059645 0.036 0.017875" rpy="0 0 0"/>
  <parent link="base_link"/>
  <child link="servo_lfs_1"/>
</joint>

<joint name="Rigid 6" type="fixed">
  <origin xyz="-0.059645 0.036 0.017875" rpy="0 0 0"/>
  <parent link="base_link"/>
  <child link="servo_lrs__1"/>
</joint>

<joint name="shrfs_joint" type="continuous">
  <origin xyz="-0.007145 -0.0125 0.004125" rpy="0 0 0"/>
  <parent link="servo_rfs_1"/>
  <child link="c_thrf__1"/>
  <axis xyz="0.0 1.0 -0.0"/>
</joint>

<joint name="Rigid 30" type="fixed">
  <origin xyz="-0.008218 0.0075 0.000719" rpy="0 0 0"/>
  <parent link="servos_rf_1"/>
  <child link="shank_rf_1"/>
</joint>

<joint name="shrft_joint" type="continuous">
  <origin xyz="0.0 0.007857 0.0" rpy="0 0 0"/>
  <parent link="c_thorf_1"/>
  <child link="servos_rf_1"/>
  <axis xyz="0.0 1.0 -0.0"/>
</joint>

<joint name="Rigid 32" type="fixed">
  <origin xyz="-0.013523 0.000445 -0.003623" rpy="0 0 0"/>
  <parent link="th_rr_1"/>
  <child link="tho_rr_1"/>
</joint>

<joint name="Rigid 33" type="fixed">
  <origin xyz="-0.02335 -0.001807 -0.00172" rpy="0 0 0"/>
  <parent link="th_rr_1"/>
  <child link="tube_rr_1"/>
</joint>

<joint name="Rigid 34" type="fixed">
  <origin xyz="0.0 -0.0023 0.0" rpy="0 0 0"/>
  <parent link="c_thrr_1"/>
  <child link="th_rr_1"/>
</joint>

<joint name="Rigid 35" type="fixed">
  <origin xyz="-0.03091 -0.004582 -0.008283" rpy="0 0 0"/>
  <parent link="tho_rr_1"/>
  <child link="c_thorr_1"/>
</joint>

<joint name="Rigid 36" type="fixed">
  <origin xyz="-0.008218 0.0075 0.000719" rpy="0 0 0"/>
  <parent link="servos_rr_1"/>
  <child link="shank_rr_1"/>
</joint>

<joint name="shrrs_joint" type="continuous">
  <origin xyz="0.007145 -0.0125 0.004125" rpy="0 0 0"/>
  <parent link="servo_rrs__1"/>
  <child link="c_thrr_1"/>
  <axis xyz="0.0 -1.0 -0.0"/>
</joint>

<joint name="shrrt_joint" type="continuous">
  <origin xyz="0.0 0.007857 0.0" rpy="0 0 0"/>
  <parent link="c_thorr_1"/>
  <child link="servos_rr_1"/>
  <axis xyz="0.0 1.0 -0.0"/>
</joint>

<joint name="Rigid 39" type="fixed">
  <origin xyz="-0.013523 -0.000445 -0.003623" rpy="0 0 0"/>
  <parent link="th_lf_1"/>
  <child link="tho_lf_1"/>
</joint>

<joint name="Rigid 40" type="fixed">
  <origin xyz="-0.02335 0.001807 -0.00172" rpy="0 0 0"/>
  <parent link="th_lf_1"/>
  <child link="tube_lf_1"/>
</joint>

<joint name="Rigid 41" type="fixed">
  <origin xyz="0.0 0.0023 0.0" rpy="0 0 0"/>
  <parent link="c_thlf_1"/>
  <child link="th_lf_1"/>
</joint>

<joint name="Rigid 42" type="fixed">
  <origin xyz="-0.03091 0.004582 -0.008283" rpy="0 0 0"/>
  <parent link="tho_lf_1"/>
  <child link="c_tholf_1"/>
</joint>

<joint name="Rigid 43" type="fixed">
  <origin xyz="-0.008218 -0.007498 0.000719" rpy="0 0 0"/>
  <parent link="servos_lf_1"/>
  <child link="shank_lf_1"/>
</joint>

<joint name="shlfs_joint" type="continuous">
  <origin xyz="-0.007145 0.0125 0.004125" rpy="0 0 0"/>
  <parent link="servo_lfs_1"/>
  <child link="c_thlf_1"/>
  <axis xyz="-0.0 1.0 0.0"/>
</joint>

<joint name="shlft_joint" type="continuous">
  <origin xyz="0.0 -0.007857 0.0" rpy="0 0 0"/>
  <parent link="c_tholf_1"/>
  <child link="servos_lf_1"/>
  <axis xyz="-0.0 1.0 0.0"/>
</joint>

<joint name="Rigid 46" type="fixed">
  <origin xyz="-0.013523 -0.000445 -0.003623" rpy="0 0 0"/>
  <parent link="th_lr__1"/>
  <child link="tho_lr_1"/>
</joint>

<joint name="Rigid 47" type="fixed">
  <origin xyz="-0.02335 0.001807 -0.00172" rpy="0 0 0"/>
  <parent link="th_lr__1"/>
  <child link="tube_lr_1"/>
</joint>

<joint name="Rigid 48" type="fixed">
  <origin xyz="0.0 0.002302 0.0" rpy="0 0 0"/>
  <parent link="c_thlr_1"/>
  <child link="th_lr__1"/>
</joint>

<joint name="Rigid 49" type="fixed">
  <origin xyz="-0.03091 0.004582 -0.008283" rpy="0 0 0"/>
  <parent link="tho_lr_1"/>
  <child link="c_tholr__1"/>
</joint>

<joint name="Rigid 50" type="fixed">
  <origin xyz="-0.008218 -0.0075 0.000719" rpy="0 0 0"/>
  <parent link="servos_lr_1"/>
  <child link="shank_lr_1"/>
</joint>

<joint name="shlrs_joint" type="continuous">
  <origin xyz="0.007145 0.0125 0.004125" rpy="0 0 0"/>
  <parent link="servo_lrs__1"/>
  <child link="c_thlr_1"/>
  <axis xyz="-0.0 -1.0 0.0"/>
</joint>

<joint name="shlrt_joint" type="continuous">
  <origin xyz="0.0 -0.007857 0.0" rpy="0 0 0"/>
  <parent link="c_tholr__1"/>
  <child link="servos_lr_1"/>
  <axis xyz="0.0 1.0 -0.0"/>
</joint>

<joint name="Rigid 58" type="fixed">
  <origin xyz="0.0 -0.031 0.030939" rpy="0 0 0"/>
  <parent link="base_link"/>
  <child link="cover_1"/>
</joint>

<joint name="Rigid 59" type="fixed">
  <origin xyz="-0.01725 0.0 0.023892" rpy="0 0 0"/>
  <parent link="base_link"/>
  <child link="battery_1"/>
</joint>

<joint name="imu_joint" type="fixed">
  <parent link="base_link"/>
  <child link="imu_link"/>
  <origin xyz="0 0 0.03"/>
</joint>

</robot>
